Workbook

Sheet acs
A1: home_county_name | B1: Ada County | C1: Adams County | D1: Bannock County | E1: Bear Lake County | F1: Benewah County | G1: Bingham County | H1: Blaine County | I1: Boise County | J1: Bonner County | K1: Bonneville County | L1: Boundary County | M1: Butte County | N1: Camas County | O1: Canyon County | P1: Caribou County | Q1: Cassia County | R1: Clark County | S1: Clearwater County | T1: Custer County | U1: Elmore County | V1: Franklin County | W1: Fremont County | X1: Gem County | Y1: Gooding County | Z1: Idaho County | AA1: Jefferson County | AB1: Jerome County | AC1: Kootenai County | AD1: Latah County | AE1: Lemhi County | AF1: Lewis County | AG1: Lincoln County | AH1: Madison County | AI1: Minidoka County | AJ1: Nez Perce County | AK1: Oneida County | AL1: Owyhee County | AM1: Payette County | AN1: Power County | AO1: Shoshone County | AP1: Teton County | AQ1: Twin Falls County | AR1: Valley County | AS1: Washington County
A2: Ada County | B2: 220996 | C2: 3 | D2: 15 | E2: 0 | F2: 0 | G2: 0 | H2: 102 | I2: 615 | J2: 0 | K2: 41 | L2: 0 | M2: 0 | N2: 0 | O2: 12017 | P2: 0 | Q2: 18 | R2: 0 | S2: 0 | T2: 16 | U2: 973 | V2: 0 | W2: 0 | X2: 348 | Y2: 24 | Z2: 122 | AA2: 0 | AB2: 19 | AC2: 0 | AD2: 0 | AE2: 0 | AF2: 0 | AG2: 9 | AH2: 19 | AI2: 37 | AJ2: 0 | AK2: 0 | AL2: 69 | AM2: 256 | AN2: 0 | AO2: 0 | AP2: 0 | AQ2: 280 | AR2: 259 | AS2: 60 | AT2: =SUM(B2:AS2) -> 236298
A3: Adams County | B3: 4 | C3: 887 | D3: 0 | E3: 0 | F3: 0 | G3: 0 | H3: 0 | I3: 0 | J3: 0 | K3: 0 | L3: 0 | M3: 0 | N3: 0 | O3: 9 | P3: 0 | Q3: 0 | R3: 0 | S3: 0 | T3: 0 | U3: 0 | V3: 0 | W3: 0 | X3: 0 | Y3: 0 | Z3: 70 | AA3: 0 | AB3: 0 | AC3: 0 | AD3: 0 | AE3: 0 | AF3: 0 | AG3: 0 | AH3: 0 | AI3: 0 | AJ3: 0 | AK3: 0 | AL3: 0 | AM3: 15 | AN3: 0 | AO3: 0 | AP3: 0 | AQ3: 8 | AR3: 520 | AS3: 12 | AT3: =SUM(B3:AS3) -> 1525
A4: Bannock County | B4: 25 | C4: 0 | D4: 31580 | E4: 0 | F4: 0 | G4: 1227 | H4: 0 | I4: 0 | J4: 0 | K4: 692 | L4: 0 | M4: 478 | N4: 0 | O4: 47 | P4: 380 | Q4: 12 | R4: 0 | S4: 0 | T4: 7 | U4: 0 | V4: 19 | W4: 10 | X4: 0 | Y4: 0 | Z4: 0 | AA4: 13 | AB4: 0 | AC4: 0 | AD4: 0 | AE4: 0 | AF4: 0 | AG4: 0 | AH4: 27 | AI4: 0 | AJ4: 0 | AK4: 105 | AL4: 0 | AM4: 0 | AN4: 735 | AO4: 0 | AP4: 0 | AQ4: 134 | AR4: 0 | AS4: 0 | AT4: =SUM(B4:AS4) -> 35491
A5: Bear Lake County | B5: 15 | C5: 0 | D5: 30 | E5: 1657 | F5: 0 | G5: 1 | H5: 0 | I5: 0 | J5: 0 | K5: 0 | L5: 0 | M5: 0 | N5: 0 | O5: 0 | P5: 485 | Q5: 0 | R5: 0 | S5: 0 | T5: 0 | U5: 0 | V5: 60 | W5: 0 | X5: 0 | Y5: 0 | Z5: 0 | AA5: 0 | AB5: 0 | AC5: 0 | AD5: 0 | AE5: 0 | AF5: 0 | AG5: 0 | AH5: 0 | AI5: 0 | AJ5: 0 | AK5: 19 | AL5: 0 | AM5: 0 | AN5: 3 | AO5: 0 | AP5: 0 | AQ5: 0 | AR5: 0 | AS5: 0 | AT5: =SUM(B5:AS5) -> 2270
A6: Benewah County | B6: 0 | C6: 0 | D6: 0 | E6: 0 | F6: 2680 | G6: 0 | H6: 0 | I6: 0 | J6: 0 | K6: 0 | L6: 0 | M6: 0 | N6: 0 | O6: 0 | P6: 0 | Q6: 0 | R6: 0 | S6: 0 | T6: 0 | U6: 0 | V6: 0 | W6: 0 | X6: 0 | Y6: 0 | Z6: 0 | AA6: 0 | AB6: 0 | AC6: 582 | AD6: 97 | AE6: 0 | AF6: 0 | AG6: 0 | AH6: 0 | AI6: 0 | AJ6: 0 | AK6: 0 | AL6: 0 | AM6: 0 | AN6: 0 | AO6: 14 | AP6: 0 | AQ6: 0 | AR6: 0 | AS6: 0 | AT6: =SUM(B6:AS6) -> 3373
A7: Bingham County | B7: 0 | C7: 0 | D7: 1084 | E7: 0 | F7: 0 | G7: 12291 | H7: 0 | I7: 0 | J7: 0 | K7: 4865 | L7: 0 | M7: 478 | N7: 0 | O7: 0 | P7: 0 | Q7: 11 | R7: 0 | S7: 0 | T7: 22 | U7: 0 | V7: 0 | W7: 0 | X7: 0 | Y7: 0 | Z7: 0 | AA7: 166 | AB7: 6 | AC7: 0 | AD7: 0 | AE7: 0 | AF7: 0 | AG7: 0 | AH7: 38 | AI7: 9 | AJ7: 0 | AK7: 0 | AL7: 0 | AM7: 0 | AN7: 415 | AO7: 0 | AP7: 0 | AQ7: 0 | AR7: 0 | AS7: 0 | AT7: =SUM(B7:AS7) -> 19385
A8: Blaine County | B8: 0 | C8: 0 | D8: 0 | E8: 0 | F8: 0 | G8: 0 | H8: 11972 | I8: 0 | J8: 0 | K8: 0 | L8: 0 | M8: 11 | N8: 35 | O8: 0 | P8: 0 | Q8: 0 | R8: 0 | S8: 0 | T8: 2 | U8: 7 | V8: 0 | W8: 0 | X8: 0 | Y8: 3 | Z8: 0 | AA8: 0 | AB8: 0 | AC8: 0 | AD8: 0 | AE8: 0 | AF8: 0 | AG8: 23 | AH8: 6 | AI8: 15 | AJ8: 0 | AK8: 0 | AL8: 0 | AM8: 0 | AN8: 0 | AO8: 0 | AP8: 0 | AQ8: 82 | AR8: 0 | AS8: 0 | AT8: =SUM(B8:AS8) -> 12156
A9: Boise County | B9: 1573 | C9: 0 | D9: 0 | E9: 0 | F9: 0 | G9: 0 | H9: 0 | I9: 1590 | J9: 0 | K9: 0 | L9: 0 | M9: 0 | N9: 0 | O9: 29 | P9: 0 | Q9: 0 | R9: 0 | S9: 0 | T9: 0 | U9: 0 | V9: 0 | W9: 0 | X9: 7 | Y9: 0 | Z9: 0 | AA9: 0 | AB9: 0 | AC9: 0 | AD9: 0 | AE9: 0 | AF9: 0 | AG9: 0 | AH9: 0 | AI9: 0 | AJ9: 9 | AK9: 0 | AL9: 0 | AM9: 0 | AN9: 0 | AO9: 0 | AP9: 0 | AQ9: 0 | AR9: 7 | AS9: 0 | AT9: =SUM(B9:AS9) -> 3215
A10: Bonner County | B10: 0 | C10: 0 | D10: 0 | E10: 0 | F10: 0 | G10: 0 | H10: 0 | I10: 0 | J10: 14713 | K10: 0 | L10: 365 | M10: 0 | N10: 0 | O10: 0 | P10: 0 | Q10: 0 | R10: 0 | S10: 0 | T10: 0 | U10: 0 | V10: 0 | W10: 0 | X10: 0 | Y10: 0 | Z10: 0 | AA10: 0 | AB10: 0 | AC10: 1488 | AD10: 16 | AE10: 0 | AF10: 0 | AG10: 0 | AH10: 0 | AI10: 0 | AJ10: 10 | AK10: 0 | AL10: 0 | AM10: 0 | AN10: 0 | AO10: 4 | AP10: 0 | AQ10: 0 | AR10: 0 | AS10: 0 | AT10: =SUM(B10:AS10) -> 16596
A11: Bonneville County | B11: 66 | C11: 0 | D11: 280 | E11: 0 | F11: 0 | G11: 1549 | H11: 0 | I11: 0 | J11: 0 | K11: 45398 | L11: 0 | M11: 1006 | N11: 0 | O11: 3 | P11: 12 | Q11: 73 | R11: 0 | S11: 0 | T11: 0 | U11: 0 | V11: 0 | W11: 139 | X11: 0 | Y11: 0 | Z11: 0 | AA11: 1640 | AB11: 0 | AC11: 0 | AD11: 0 | AE11: 0 | AF11: 0 | AG11: 0 | AH11: 1025 | AI11: 0 | AJ11: 0 | AK11: 0 | AL11: 0 | AM11: 0 | AN11: 0 | AO11: 0 | AP11: 90 | AQ11: 93 | AR11: 0 | AS11: 0 | AT11: =SUM(B11:AS11) -> 51374
A12: Boundary County | B12: 0 | C12: 0 | D12: 0 | E12: 0 | F12: 0 | G12: 0 | H12: 0 | I12: 0 | J12: 345 | K12: 0 | L12: 4067 | M12: 0 | N12: 0 | O12: 0 | P12: 0 | Q12: 0 | R12: 0 | S12: 0 | T12: 0 | U12: 0 | V12: 0 | W12: 0 | X12: 0 | Y12: 0 | Z12: 0 | AA12: 0 | AB12: 0 | AC12: 114 | AD12: 0 | AE12: 0 | AF12: 0 | AG12: 0 | AH12: 0 | AI12: 0 | AJ12: 0 | AK12: 0 | AL12: 0 | AM12: 0 | AN12: 0 | AO12: 0 | AP12: 0 | AQ12: 0 | AR12: 0 | AS12: 0 | AT12: =SUM(B12:AS12) -> 4526
A13: Butte County | B13: 0 | C13: 0 | D13: 5 | E13: 0 | F13: 0 | G13: 4 | H13: 0 | I13: 0 | J13: 0 | K13: 122 | L13: 0 | M13: 871 | N13: 0 | O13: 0 | P13: 0 | Q13: 0 | R13: 0 | S13: 0 | T13: 12 | U13: 0 | V13: 0 | W13: 0 | X13: 0 | Y13: 0 | Z13: 0 | AA13: 0 | AB13: 0 | AC13: 0 | AD13: 0 | AE13: 0 | AF13: 0 | AG13: 0 | AH13: 0 | AI13: 0 | AJ13: 0 | AK13: 0 | AL13: 0 | AM13: 0 | AN13: 0 | AO13: 0 | AP13: 0 | AQ13: 0 | AR13: 0 | AS13: 0 | AT13: =SUM(B13:AS13) -> 1014
... A45: Washington County | B45: 178 | C45: 17 | D45: 0 | E45: 0 | F45: 0 | G45: 0 | H45: 0 | I45: 0 | J45: 0 | K45: 0 | L45: 0 | M45: 0 | N45: 0 | O45: 80 | P45: 0 | Q45: 0 | R45: 0 | S45: 0 | T45: 0 | U45: 0 | V45: 0 | W45: 0 | X45: 14 | Y45: 0 | Z45: 0 | AA45: 0 | AB45: 0 | AC45: 0 | AD45: 0 | AE45: 0 | AF45: 0 | AG45: 0 | AH45: 0 | AI45: 0 | AJ45: 0 | AK45: 0 | AL45: 0 | AM45: 125 | AN45: 0 | AO45: 0 | AP45: 0 | AQ45: 0 | AR45: 0 | AS45: 2661 | AT45: =SUM(B45:AS45) -> 3075
B46: =SUM(B2:B45) -> 260709 | C46: =SUM(C2:C45) -> 997 | D46: =SUM(D2:D45) -> 34195 | E46: =SUM(E2:E45) -> 1749 | F46: =SUM(F2:F45) -> 3689 | G46: =SUM(G2:G45) -> 15599 | H46: =SUM(H2:H45) -> 13427 | I46: =SUM(I2:I45) -> 2327 | ... AS46: =SUM(AS2:AS45) -> 3033 | AT46: =SUM(B46:AS46) -> 765873

Sheet model
A1: 2020 Model | B1: Ada County | C1: Adams County | D1: Bannock County | E1: Bear Lake County | F1: Benewah County | G1: Bingham County | H1: Blaine County | I1: Boise County | J1: Bonner County | K1: Bonneville County | L1: Boundary County | M1: Butte County | N1: Camas County | O1: Canyon County | P1: Caribou County | Q1: Cassia County | R1: Clark County | S1: Clearwater County | T1: Custer County | U1: Elmore County | V1: Franklin County | W1: Fremont County | X1: Gem County | Y1: Gooding County | Z1: Idaho County | AA1: Jefferson County | AB1: Jerome County | AC1: Kootenai County | AD1: Latah County | AE1: Lemhi County | AF1: Lewis County | AG1: Lincoln County | AH1: Madison County | AI1: Minidoka County | AJ1: Nez Perce County | AK1: Oneida County | AL1: Owyhee County | AM1: Payette County | AN1: Power County | AO1: Shoshone County | AP1: Teton County | AQ1: Twin Falls County | AR1: Valley County | AS1: Washington County | AT1: Total
A2: Ada County | B2: 260250 | C2: 1 | D2: 67 | E2: 0 | F2: 0 | G2: 8 | H2: 54 | I2: 27 | J2: 0 | K2: 186 | L2: 0 | M2: 6 | N2: 5 | O2: 12502 | P2: 0 | Q2: 36 | R2: 1 | S2: 0 | T2: 1 | U2: 120 | V2: 0 | W2: 0 | X2: 176 | Y2: 97 | Z2: 1 | AA2: 9 | AB2: 63 | AC2: 0 | AD2: 0 | AE2: 0 | AF2: 0 | AG2: 16 | AH2: 3 | AI2: 24 | AJ2: 0 | AK2: 0 | AL2: 156 | AM2: 205 | AN2: 12 | AO2: 0 | AP2: 0 | AQ2: 255 | AR2: 29 | AS2: 49 | AT2: =SUM(B2:AS2) -> 274359
A3: Adams County | B3: 126 | C3: 2178 | D3: 0 | E3: 0 | F3: 0 | G3: 0 | H3: 0 | I3: 0 | J3: 0 | K3: 0 | L3: 0 | M3: 0 | N3: 0 | O3: 85 | P3: 0 | Q3: 0 | R3: 0 | S3: 0 | T3: 0 | U3: 0 | V3: 0 | W3: 0 | X3: 1 | Y3: 0 | Z3: 6 | AA3: 0 | AB3: 0 | AC3: 1 | AD3: 0 | AE3: 0 | AF3: 3 | AG3: 0 | AH3: 0 | AI3: 0 | AJ3: 8 | AK3: 0 | AL3: 0 | AM3: 16 | AN3: 0 | AO3: 0 | AP3: 0 | AQ3: 1 | AR3: 26 | AS3: 20 | AT3: =SUM(B3:AS3) -> 2471
A4: Bannock County | B4: 9 | C4: 0 | D4: 35624 | E4: 1 | F4: 0 | G4: 783 | H4: 9 | I4: 0 | J4: 0 | K4: 12299 | L4: 0 | M4: 28 | N4: 1 | O4: 3 | P4: 97 | Q4: 66 | R4: 12 | S4: 0 | T4: 3 | U4: 0 | V4: 32 | W4: 10 | X4: 0 | Y4: 3 | Z4: 0 | AA4: 198 | AB4: 12 | AC4: 0 | AD4: 0 | AE4: 1 | AF4: 0 | AG4: 3 | AH4: 118 | AI4: 31 | AJ4: 0 | AK4: 60 | AL4: 0 | AM4: 0 | AN4: 411 | AO4: 0 | AP4: 3 | AQ4: 61 | AR4: 0 | AS4: 0 | AT4: =SUM(B4:AS4) -> 49878
A5: Bear Lake County | B5: 2 | C5: 0 | D5: 213 | E5: 2560 | F5: 0 | G5: 26 | H5: 0 | I5: 0 | J5: 0 | K5: 409 | L5: 0 | M5: 0 | N5: 0 | O5: 0 | P5: 66 | Q5: 1 | R5: 1 | S5: 0 | T5: 0 | U5: 0 | V5: 11 | W5: 0 | X5: 0 | Y5: 0 | Z5: 0 | AA5: 8 | AB5: 0 | AC5: 0 | AD5: 0 | AE5: 0 | AF5: 0 | AG5: 0 | AH5: 9 | AI5: 1 | AJ5: 0 | AK5: 4 | AL5: 0 | AM5: 0 | AN5: 19 | AO5: 0 | AP5: 0 | AQ5: 1 | AR5: 0 | AS5: 0 | AT5: =SUM(B5:AS5) -> 3331
A6: Benewah County | B6: 0 | C6: 0 | D6: 0 | E6: 0 | F6: 3085 | G6: 0 | H6: 0 | I6: 0 | J6: 10 | K6: 0 | L6: 0 | M6: 0 | N6: 0 | O6: 0 | P6: 0 | Q6: 0 | R6: 0 | S6: 2 | T6: 0 | U6: 0 | V6: 0 | W6: 0 | X6: 0 | Y6: 0 | Z6: 1 | AA6: 0 | AB6: 0 | AC6: 1657 | AD6: 62 | AE6: 0 | AF6: 0 | AG6: 0 | AH6: 0 | AI6: 0 | AJ6: 63 | AK6: 0 | AL6: 0 | AM6: 0 | AN6: 0 | AO6: 59 | AP6: 0 | AQ6: 0 | AR6: 0 | AS6: 0 | AT6: =SUM(B6:AS6) -> 4939
A7: Bingham County | B7: 0 | C7: 0 | D7: 1697 | E7: 0 | F7: 0 | G7: 12717 | H7: 5 | I7: 0 | J7: 0 | K7: 10866 | L7: 0 | M7: 13 | N7: 0 | O7: 0 | P7: 11 | Q7: 14 | R7: 7 | S7: 0 | T7: 1 | U7: 0 | V7: 4 | W7: 4 | X7: 0 | Y7: 0 | Z7: 0 | AA7: 166 | AB7: 1 | AC7: 0 | AD7: 0 | AE7: 1 | AF7: 0 | AG7: 0 | AH7: 71 | AI7: 6 | AJ7: 0 | AK7: 5 | AL7: 0 | AM7: 0 | AN7: 82 | AO7: 0 | AP7: 5 | AQ7: 9 | AR7: 0 | AS7: 0 | AT7: =SUM(B7:AS7) -> 25685
A8: Blaine County | B8: 17 | C8: 0 | D8: 36 | E8: 0 | F8: 0 | G8: 19 | H8: 13235 | I8: 0 | J8: 0 | K8: 378 | L8: 0 | M8: 9 | N8: 2 | O8: 10 | P8: 0 | Q8: 7 | R8: 1 | S8: 0 | T8: 5 | U8: 3 | V8: 0 | W8: 1 | X8: 0 | Y8: 17 | Z8: 0 | AA8: 7 | AB8: 21 | AC8: 0 | AD8: 0 | AE8: 0 | AF8: 0 | AG8: 11 | AH8: 3 | AI8: 6 | AJ8: 0 | AK8: 0 | AL8: 0 | AM8: 0 | AN8: 0 | AO8: 0 | AP8: 0 | AQ8: 92 | AR8: 0 | AS8: 0 | AT8: =SUM(B8:AS8) -> 13880
A9: Boise County | B9: 1747 | C9: 0 | D9: 5 | E9: 0 | F9: 0 | G9: 0 | H9: 4 | I9: 2161 | J9: 0 | K9: 8 | L9: 0 | M9: 0 | N9: 1 | O9: 425 | P9: 0 | Q9: 2 | R9: 0 | S9: 0 | T9: 1 | U9: 4 | V9: 0 | W9: 0 | X9: 18 | Y9: 2 | Z9: 0 | AA9: 0 | AB9: 3 | AC9: 0 | AD9: 0 | AE9: 0 | AF9: 0 | AG9: 0 | AH9: 0 | AI9: 5 | AJ9: 2 | AK9: 0 | AL9: 4 | AM9: 14 | AN9: 0 | AO9: 0 | AP9: 0 | AQ9: 14 | AR9: 9 | AS9: 2 | AT9: =SUM(B9:AS9) -> 4431
A10: Bonner County | B10: 0 | C10: 0 | D10: 0 | E10: 0 | F10: 40 | G10: 0 | H10: 0 | I10: 0 | J10: 17749 | K10: 0 | L10: 56 | M10: 0 | N10: 0 | O10: 0 | P10: 0 | Q10: 0 | R10: 0 | S10: 0 | T10: 0 | U10: 0 | V10: 0 | W10: 0 | X10: 0 | Y10: 0 | Z10: 0 | AA10: 0 | AB10: 0 | AC10: 6598 | AD10: 15 | AE10: 0 | AF10: 0 | AG10: 0 | AH10: 0 | AI10: 0 | AJ10: 14 | AK10: 0 | AL10: 0 | AM10: 0 | AN10: 0 | AO10: 67 | AP10: 0 | AQ10: 0 | AR10: 0 | AS10: 0 | AT10: =SUM(B10:AS10) -> 24539
A11: Bonneville County | B11: 2 | C11: 0 | D11: 586 | E11: 0 | F11: 0 | G11: 225 | H11: 0 | I11: 0 | J11: 0 | K11: 35752 | L11: 0 | M11: 9 | N11: 0 | O11: 2 | P11: 4 | Q11: 6 | R11: 16 | S11: 0 | T11: 0 | U11: 0 | V11: 2 | W11: 7 | X11: 0 | Y11: 1 | Z11: 0 | AA11: 367 | AB11: 2 | AC11: 0 | AD11: 0 | AE11: 0 | AF11: 0 | AG11: 0 | AH11: 167 | AI11: 4 | AJ11: 0 | AK11: 1 | AL11: 0 | AM11: 0 | AN11: 23 | AO11: 0 | AP11: 3 | AQ11: 6 | AR11: 0 | AS11: 0 | AT11: =SUM(B11:AS11) -> 37185
A12: Boundary County | B12: 0 | C12: 0 | D12: 0 | E12: 0 | F12: 21 | G12: 0 | H12: 0 | I12: 0 | J12: 208 | K12: 0 | L12: 4415 | M12: 0 | N12: 0 | O12: 0 | P12: 0 | Q12: 0 | R12: 0 | S12: 0 | T12: 0 | U12: 0 | V12: 0 | W12: 0 | X12: 0 | Y12: 0 | Z12: 0 | AA12: 0 | AB12: 0 | AC12: 1690 | AD12: 2 | AE12: 0 | AF12: 1 | AG12: 0 | AH12: 0 | AI12: 0 | AJ12: 1 | AK12: 0 | AL12: 0 | AM12: 0 | AN12: 0 | AO12: 17 | AP12: 0 | AQ12: 0 | AR12: 0 | AS12: 0 | AT12: =SUM(B12:AS12) -> 6355
A13: Butte County | B13: 4 | C13: 0 | D13: 82 | E13: 0 | F13: 0 | G13: 29 | H13: 11 | I13: 0 | J13: 0 | K13: 830 | L13: 0 | M13: 453 | N13: 0 | O13: 0 | P13: 0 | Q13: 1 | R13: 0 | S13: 0 | T13: 5 | U13: 0 | V13: 0 | W13: 0 | X13: 0 | Y13: 0 | Z13: 0 | AA13: 19 | AB13: 0 | AC13: 0 | AD13: 0 | AE13: 0 | AF13: 0 | AG13: 0 | AH13: 7 | AI13: 0 | AJ13: 0 | AK13: 0 | AL13: 0 | AM13: 0 | AN13: 5 | AO13: 0 | AP13: 1 | AQ13: 1 | AR13: 0 | AS13: 0 | AT13: =SUM(B13:AS13) -> 1448
... A45: Washington County | B45: 1052 | C45: 5 | D45: 1 | E45: 0 | F45: 0 | G45: 0 | H45: 3 | I45: 2 | J45: 0 | K45: 0 | L45: 0 | M45: 0 | N45: 0 | O45: 732 | P45: 0 | Q45: 1 | R45: 0 | S45: 0 | T45: 0 | U45: 3 | V45: 0 | W45: 0 | X45: 30 | Y45: 0 | Z45: 3 | AA45: 0 | AB45: 1 | AC45: 0 | AD45: 0 | AE45: 0 | AF45: 0 | AG45: 0 | AH45: 0 | AI45: 0 | AJ45: 3 | AK45: 0 | AL45: 13 | AM45: 104 | AN45: 0 | AO45: 0 | AP45: 0 | AQ45: 11 | AR45: 6 | AS45: 3507 | AT45: =SUM(B45:AS45) -> 5477
A46: Total | B46: =SUM(B2:B45) -> 318899 | C46: =SUM(C2:C45) -> 2213 | D46: =SUM(D2:D45) -> 49379 | E46: =SUM(E2:E45) -> 2573 | F46: =SUM(F2:F45) -> 3502 | G46: =SUM(G2:G45) -> 15093 | H46: =SUM(H2:H45) -> 14867 | I46: =SUM(I2:I45) -> 2245 | ... AS46: =SUM(AS2:AS45) -> 3832 | AT46: =SUM(B46:AS46) -> 972431

Sheet diff
A1: home_county_name | B1: Ada County | C1: Adams County | D1: Bannock County | E1: Bear Lake County | F1: Benewah County | G1: Bingham County | H1: Blaine County | I1: Boise County | J1: Bonner County | K1: Bonneville County | L1: Boundary County | M1: Butte County | N1: Camas County | O1: Canyon County | P1: Caribou County | Q1: Cassia County | R1: Clark County | S1: Clearwater County | T1: Custer County | U1: Elmore County | V1: Franklin County | W1: Fremont County | X1: Gem County | Y1: Gooding County | Z1: Idaho County | AA1: Jefferson County | AB1: Jerome County | AC1: Kootenai County | AD1: Latah County | AE1: Lemhi County | AF1: Lewis County | AG1: Lincoln County | AH1: Madison County | AI1: Minidoka County | AJ1: Nez Perce County | AK1: Oneida County | AL1: Owyhee County | AM1: Payette County | AN1: Power County | AO1: Shoshone County | AP1: Teton County | AQ1: Twin Falls County | AR1: Valley County | AS1: Washington County
A2: Ada County | B2: -39254 | C2: 2 | D2: -52 | E2: 0 | F2: 0 | G2: -8 | H2: 48 | I2: 588 | J2: 0 | K2: -145 | L2: 0 | M2: -6 | N2: -5 | O2: -485 | P2: 0 | Q2: -18 | R2: -1 | S2: 0 | T2: 15 | U2: 853 | V2: 0 | W2: 0 | X2: 172 | Y2: -73 | Z2: 121 | AA2: -9 | AB2: -44 | AC2: 0 | AD2: 0 | AE2: 0 | AF2: 0 | AG2: -7 | AH2: 16 | AI2: 13 | AJ2: 0 | AK2: 0 | AL2: -87 | AM2: 51 | AN2: -12 | AO2: 0 | AP2: 0 | AQ2: 25 | AR2: 230 | AS2: 11
A3: Adams County | B3: -122 | C3: -1291 | D3: 0 | E3: 0 | F3: 0 | G3: 0 | H3: 0 | I3: 0 | J3: 0 | K3: 0 | L3: 0 | M3: 0 | N3: 0 | O3: -76 | P3: 0 | Q3: 0 | R3: 0 | S3: 0 | T3: 0 | U3: 0 | V3: 0 | W3: 0 | X3: -1 | Y3: 0 | Z3: 64 | AA3: 0 | AB3: 0 | AC3: -1 | AD3: 0 | AE3: 0 | AF3: -3 | AG3: 0 | AH3: 0 | AI3: 0 | AJ3: -8 | AK3: 0 | AL3: 0 | AM3: -1 | AN3: 0 | AO3: 0 | AP3: 0 | AQ3: 7 | AR3: 494 | AS3: -8
A4: Bannock County | B4: 16 | C4: 0 | D4: -4044 | E4: -1 | F4: 0 | G4: 444 | H4: -9 | I4: 0 | J4: 0 | K4: -11607 | L4: 0 | M4: 450 | N4: -1 | O4: 44 | P4: 283 | Q4: -54 | R4: -12 | S4: 0 | T4: 4 | U4: 0 | V4: -13 | W4: 0 | X4: 0 | Y4: -3 | Z4: 0 | AA4: -185 | AB4: -12 | AC4: 0 | AD4: 0 | AE4: -1 | AF4: 0 | AG4: -3 | AH4: -91 | AI4: -31 | AJ4: 0 | AK4: 45 | AL4: 0 | AM4: 0 | AN4: 324 | AO4: 0 | AP4: -3 | AQ4: 73 | AR4: 0 | AS4: 0
A5: Bear Lake County | B5: 13 | C5: 0 | D5: -183 | E5: -903 | F5: 0 | G5: -25 | H5: 0 | I5: 0 | J5: 0 | K5: -409 | L5: 0 | M5: 0 | N5: 0 | O5: 0 | P5: 419 | Q5: -1 | R5: -1 | S5: 0 | T5: 0 | U5: 0 | V5: 49 | W5: 0 | X5: 0 | Y5: 0 | Z5: 0 | AA5: -8 | AB5: 0 | AC5: 0 | AD5: 0 | AE5: 0 | AF5: 0 | AG5: 0 | AH5: -9 | AI5: -1 | AJ5: 0 | AK5: 15 | AL5: 0 | AM5: 0 | AN5: -16 | AO5: 0 | AP5: 0 | AQ5: -1 | AR5: 0 | AS5: 0
A6: Benewah County | B6: 0 | C6: 0 | D6: 0 | E6: 0 | F6: -405 | G6: 0 | H6: 0 | I6: 0 | J6: -10 | K6: 0 | L6: 0 | M6: 0 | N6: 0 | O6: 0 | P6: 0 | Q6: 0 | R6: 0 | S6: -2 | T6: 0 | U6: 0 | V6: 0 | W6: 0 | X6: 0 | Y6: 0 | Z6: -1 | AA6: 0 | AB6: 0 | AC6: -1075 | AD6: 35 | AE6: 0 | AF6: 0 | AG6: 0 | AH6: 0 | AI6: 0 | AJ6: -63 | AK6: 0 | AL6: 0 | AM6: 0 | AN6: 0 | AO6: -45 | AP6: 0 | AQ6: 0 | AR6: 0 | AS6: 0
A7: Bingham County | B7: 0 | C7: 0 | D7: -613 | E7: 0 | F7: 0 | G7: -426 | H7: -5 | I7: 0 | J7: 0 | K7: -6001 | L7: 0 | M7: 465 | N7: 0 | O7: 0 | P7: -11 | Q7: -3 | R7: -7 | S7: 0 | T7: 21 | U7: 0 | V7: -4 | W7: -4 | X7: 0 | Y7: 0 | Z7: 0 | AA7: 0 | AB7: 5 | AC7: 0 | AD7: 0 | AE7: -1 | AF7: 0 | AG7: 0 | AH7: -33 | AI7: 3 | AJ7: 0 | AK7: -5 | AL7: 0 | AM7: 0 | AN7: 333 | AO7: 0 | AP7: -5 | AQ7: -9 | AR7: 0 | AS7: 0
A8: Blaine County | B8: -17 | C8: 0 | D8: -36 | E8: 0 | F8: 0 | G8: -19 | H8: -1263 | I8: 0 | J8: 0 | K8: -378 | L8: 0 | M8: 2 | N8: 33 | O8: -10 | P8: 0 | Q8: -7 | R8: -1 | S8: 0 | T8: -3 | U8: 4 | V8: 0 | W8: -1 | X8: 0 | Y8: -14 | Z8: 0 | AA8: -7 | AB8: -21 | AC8: 0 | AD8: 0 | AE8: 0 | AF8: 0 | AG8: 12 | AH8: 3 | AI8: 9 | AJ8: 0 | AK8: 0 | AL8: 0 | AM8: 0 | AN8: 0 | AO8: 0 | AP8: 0 | AQ8: -10 | AR8: 0 | AS8: 0
A9: Boise County | B9: -174 | C9: 0 | D9: -5 | E9: 0 | F9: 0 | G9: 0 | H9: -4 | I9: -571 | J9: 0 | K9: -8 | L9: 0 | M9: 0 | N9: -1 | O9: -396 | P9: 0 | Q9: -2 | R9: 0 | S9: 0 | T9: -1 | U9: -4 | V9: 0 | W9: 0 | X9: -11 | Y9: -2 | Z9: 0 | AA9: 0 | AB9: -3 | AC9: 0 | AD9: 0 | AE9: 0 | AF9: 0 | AG9: 0 | AH9: 0 | AI9: -5 | AJ9: 7 | AK9: 0 | AL9: -4 | AM9: -14 | AN9: 0 | AO9: 0 | AP9: 0 | AQ9: -14 | AR9: -2 | AS9: -2
A10: Bonner County | B10: 0 | C10: 0 | D10: 0 | E10: 0 | F10: -40 | G10: 0 | H10: 0 | I10: 0 | J10: -3036 | K10: 0 | L10: 309 | M10: 0 | N10: 0 | O10: 0 | P10: 0 | Q10: 0 | R10: 0 | S10: 0 | T10: 0 | U10: 0 | V10: 0 | W10: 0 | X10: 0 | Y10: 0 | Z10: 0 | AA10: 0 | AB10: 0 | AC10: -5110 | AD10: 1 | AE10: 0 | AF10: 0 | AG10: 0 | AH10: 0 | AI10: 0 | AJ10: -4 | AK10: 0 | AL10: 0 | AM10: 0 | AN10: 0 | AO10: -63 | AP10: 0 | AQ10: 0 | AR10: 0 | AS10: 0
A11: Bonneville County | B11: 64 | C11: 0 | D11: -306 | E11: 0 | F11: 0 | G11: 1324 | H11: 0 | I11: 0 | J11: 0 | K11: 9646 | L11: 0 | M11: 997 | N11: 0 | O11: 1 | P11: 8 | Q11: 67 | R11: -16 | S11: 0 | T11: 0 | U11: 0 | V11: -2 | W11: 132 | X11: 0 | Y11: -1 | Z11: 0 | AA11: 1273 | AB11: -2 | AC11: 0 | AD11: 0 | AE11: 0 | AF11: 0 | AG11: 0 | AH11: 858 | AI11: -4 | AJ11: 0 | AK11: -1 | AL11: 0 | AM11: 0 | AN11: -23 | AO11: 0 | AP11: 87 | AQ11: 87 | AR11: 0 | AS11: 0
A12: Boundary County | B12: 0 | C12: 0 | D12: 0 | E12: 0 | F12: -21 | G12: 0 | H12: 0 | I12: 0 | J12: 137 | K12: 0 | L12: -348 | M12: 0 | N12: 0 | O12: 0 | P12: 0 | Q12: 0 | R12: 0 | S12: 0 | T12: 0 | U12: 0 | V12: 0 | W12: 0 | X12: 0 | Y12: 0 | Z12: 0 | AA12: 0 | AB12: 0 | AC12: -1576 | AD12: -2 | AE12: 0 | AF12: -1 | AG12: 0 | AH12: 0 | AI12: 0 | AJ12: -1 | AK12: 0 | AL12: 0 | AM12: 0 | AN12: 0 | AO12: -17 | AP12: 0 | AQ12: 0 | AR12: 0 | AS12: 0
A13: Butte County | B13: -4 | C13: 0 | D13: -77 | E13: 0 | F13: 0 | G13: -25 | H13: -11 | I13: 0 | J13: 0 | K13: -708 | L13: 0 | M13: 418 | N13: 0 | O13: 0 | P13: 0 | Q13: -1 | R13: 0 | S13: 0 | T13: 7 | U13: 0 | V13: 0 | W13: 0 | X13: 0 | Y13: 0 | Z13: 0 | AA13: -19 | AB13: 0 | AC13: 0 | AD13: 0 | AE13: 0 | AF13: 0 | AG13: 0 | AH13: -7 | AI13: 0 | AJ13: 0 | AK13: 0 | AL13: 0 | AM13: 0 | AN13: -5 | AO13: 0 | AP13: -1 | AQ13: -1 | AR13: 0 | AS13: 0
... A45: Washington County | B45: -874 | C45: 12 | D45: -1 | E45: 0 | F45: 0 | G45: 0 | H45: -3 | I45: -2 | J45: 0 | K45: 0 | L45: 0 | M45: 0 | N45: 0 | O45: -652 | P45: 0 | Q45: -1 | R45: 0 | S45: 0 | T45: 0 | U45: -3 | V45: 0 | W45: 0 | X45: -16 | Y45: 0 | Z45: -3 | AA45: 0 | AB45: -1 | AC45: 0 | AD45: 0 | AE45: 0 | AF45: 0 | AG45: 0 | AH45: 0 | AI45: 0 | AJ45: -3 | AK45: 0 | AL45: -13 | AM45: 21 | AN45: 0 | AO45: 0 | AP45: 0 | AQ45: -11 | AR45: -6 | AS45: -846

Sheet IPF ACS to ASIM
A1: ACS County Flows | B1: Ada County | C1: Adams County | D1: Bannock County | E1: Bear Lake County | F1: Benewah County | G1: Bingham County | H1: Blaine County | I1: Boise County | J1: Bonner County | K1: Bonneville County | L1: Boundary County | M1: Butte County | N1: Camas County | O1: Canyon County | P1: Caribou County | Q1: Cassia County | R1: Clark County | S1: Clearwater County | T1: Custer County | U1: Elmore County | V1: Franklin County | W1: Fremont County | X1: Gem County | Y1: Gooding County | Z1: Idaho County | AA1: Jefferson County | AB1: Jerome County | AC1: Kootenai County | AD1: Latah County | AE1: Lemhi County | AF1: Lewis County | AG1: Lincoln County | AH1: Madison County | AI1: Minidoka County | AJ1: Nez Perce County | AK1: Oneida County | AL1: Owyhee County | AM1: Payette County | AN1: Power County | AO1: Shoshone County | AP1: Teton County | AQ1: Twin Falls County | AR1: Valley County | AS1: Washington County | AT1: ACS Total | AU1: Model Total
A2: Ada County | B2: 220996 | C2: 3 | D2: 15 | E2: 0 | F2: 0 | G2: 0 | H2: 102 | I2: 615 | J2: 0 | K2: 41 | L2: 0 | M2: 0 | N2: 0 | O2: 12017 | P2: 0 | Q2: 18 | R2: 0 | S2: 0 | T2: 16 | U2: 973 | V2: 0 | W2: 0 | X2: 348 | Y2: 24 | Z2: 122 | AA2: 0 | AB2: 19 | AC2: 0 | AD2: 0 | AE2: 0 | AF2: 0 | AG2: 9 | AH2: 19 | AI2: 37 | AJ2: 0 | AK2: 0 | AL2: 69 | AM2: 256 | AN2: 0 | AO2: 0 | AP2: 0 | AQ2: 280 | AR2: 259 | AS2: 60 | AT2: =SUM(B2:AS2) -> 236298 | AU2: =model!AT2 -> 274359
A3: Adams County | B3: 4 | C3: 887 | D3: 0 | E3: 0 | F3: 0 | G3: 0 | H3: 0 | I3: 0 | J3: 0 | K3: 0 | L3: 0 | M3: 0 | N3: 0 | O3: 9 | P3: 0 | Q3: 0 | R3: 0 | S3: 0 | T3: 0 | U3: 0 | V3: 0 | W3: 0 | X3: 0 | Y3: 0 | Z3: 70 | AA3: 0 | AB3: 0 | AC3: 0 | AD3: 0 | AE3: 0 | AF3: 0 | AG3: 0 | AH3: 0 | AI3: 0 | AJ3: 0 | AK3: 0 | AL3: 0 | AM3: 15 | AN3: 0 | AO3: 0 | AP3: 0 | AQ3: 8 | AR3: 520 | AS3: 12 | AT3: =SUM(B3:AS3) -> 1525 | AU3: =model!AT3 -> 2471
A4: Bannock County | B4: 25 | C4: 0 | D4: 31580 | E4: 0 | F4: 0 | G4: 1227 | H4: 0 | I4: 0 | J4: 0 | K4: 692 | L4: 0 | M4: 478 | N4: 0 | O4: 47 | P4: 380 | Q4: 12 | R4: 0 | S4: 0 | T4: 7 | U4: 0 | V4: 19 | W4: 10 | X4: 0 | Y4: 0 | Z4: 0 | AA4: 13 | AB4: 0 | AC4: 0 | AD4: 0 | AE4: 0 | AF4: 0 | AG4: 0 | AH4: 27 | AI4: 0 | AJ4: 0 | AK4: 105 | AL4: 0 | AM4: 0 | AN4: 735 | AO4: 0 | AP4: 0 | AQ4: 134 | AR4: 0 | AS4: 0 | AT4: =SUM(B4:AS4) -> 35491 | AU4: =model!AT4 -> 49878
A5: Bear Lake County | B5: 15 | C5: 0 | D5: 30 | E5: 1657 | F5: 0 | G5: 1 | H5: 0 | I5: 0 | J5: 0 | K5: 0 | L5: 0 | M5: 0 | N5: 0 | O5: 0 | P5: 485 | Q5: 0 | R5: 0 | S5: 0 | T5: 0 | U5: 0 | V5: 60 | W5: 0 | X5: 0 | Y5: 0 | Z5: 0 | AA5: 0 | AB5: 0 | AC5: 0 | AD5: 0 | AE5: 0 | AF5: 0 | AG5: 0 | AH5: 0 | AI5: 0 | AJ5: 0 | AK5: 19 | AL5: 0 | AM5: 0 | AN5: 3 | AO5: 0 | AP5: 0 | AQ5: 0 | AR5: 0 | AS5: 0 | AT5: =SUM(B5:AS5) -> 2270 | AU5: =model!AT5 -> 3331
A6: Benewah County | B6: 0 | C6: 0 | D6: 0 | E6: 0 | F6: 2680 | G6: 0 | H6: 0 | I6: 0 | J6: 0 | K6: 0 | L6: 0 | M6: 0 | N6: 0 | O6: 0 | P6: 0 | Q6: 0 | R6: 0 | S6: 0 | T6: 0 | U6: 0 | V6: 0 | W6: 0 | X6: 0 | Y6: 0 | Z6: 0 | AA6: 0 | AB6: 0 | AC6: 582 | AD6: 97 | AE6: 0 | AF6: 0 | AG6: 0 | AH6: 0 | AI6: 0 | AJ6: 0 | AK6: 0 | AL6: 0 | AM6: 0 | AN6: 0 | AO6: 14 | AP6: 0 | AQ6: 0 | AR6: 0 | AS6: 0 | AT6: =SUM(B6:AS6) -> 3373 | AU6: =model!AT6 -> 4939
A7: Bingham County | B7: 0 | C7: 0 | D7: 1084 | E7: 0 | F7: 0 | G7: 12291 | H7: 0 | I7: 0 | J7: 0 | K7: 4865 | L7: 0 | M7: 478 | N7: 0 | O7: 0 | P7: 0 | Q7: 11 | R7: 0 | S7: 0 | T7: 22 | U7: 0 | V7: 0 | W7: 0 | X7: 0 | Y7: 0 | Z7: 0 | AA7: 166 | AB7: 6 | AC7: 0 | AD7: 0 | AE7: 0 | AF7: 0 | AG7: 0 | AH7: 38 | AI7: 9 | AJ7: 0 | AK7: 0 | AL7: 0 | AM7: 0 | AN7: 415 | AO7: 0 | AP7: 0 | AQ7: 0 | AR7: 0 | AS7: 0 | AT7: =SUM(B7:AS7) -> 19385 | AU7: =model!AT7 -> 25685
A8: Blaine County | B8: 0 | C8: 0 | D8: 0 | E8: 0 | F8: 0 | G8: 0 | H8: 11972 | I8: 0 | J8: 0 | K8: 0 | L8: 0 | M8: 11 | N8: 35 | O8: 0 | P8: 0 | Q8: 0 | R8: 0 | S8: 0 | T8: 2 | U8: 7 | V8: 0 | W8: 0 | X8: 0 | Y8: 3 | Z8: 0 | AA8: 0 | AB8: 0 | AC8: 0 | AD8: 0 | AE8: 0 | AF8: 0 | AG8: 23 | AH8: 6 | AI8: 15 | AJ8: 0 | AK8: 0 | AL8: 0 | AM8: 0 | AN8: 0 | AO8: 0 | AP8: 0 | AQ8: 82 | AR8: 0 | AS8: 0 | AT8: =SUM(B8:AS8) -> 12156 | AU8: =model!AT8 -> 13880
A9: Boise County | B9: 1573 | C9: 0 | D9: 0 | E9: 0 | F9: 0 | G9: 0 | H9: 0 | I9: 1590 | J9: 0 | K9: 0 | L9: 0 | M9: 0 | N9: 0 | O9: 29 | P9: 0 | Q9: 0 | R9: 0 | S9: 0 | T9: 0 | U9: 0 | V9: 0 | W9: 0 | X9: 7 | Y9: 0 | Z9: 0 | AA9: 0 | AB9: 0 | AC9: 0 | AD9: 0 | AE9: 0 | AF9: 0 | AG9: 0 | AH9: 0 | AI9: 0 | AJ9: 9 | AK9: 0 | AL9: 0 | AM9: 0 | AN9: 0 | AO9: 0 | AP9: 0 | AQ9: 0 | AR9: 7 | AS9: 0 | AT9: =SUM(B9:AS9) -> 3215 | AU9: =model!AT9 -> 4431
A10: Bonner County | B10: 0 | C10: 0 | D10: 0 | E10: 0 | F10: 0 | G10: 0 | H10: 0 | I10: 0 | J10: 14713 | K10: 0 | L10: 365 | M10: 0 | N10: 0 | O10: 0 | P10: 0 | Q10: 0 | R10: 0 | S10: 0 | T10: 0 | U10: 0 | V10: 0 | W10: 0 | X10: 0 | Y10: 0 | Z10: 0 | AA10: 0 | AB10: 0 | AC10: 1488 | AD10: 16 | AE10: 0 | AF10: 0 | AG10: 0 | AH10: 0 | AI10: 0 | AJ10: 10 | AK10: 0 | AL10: 0 | AM10: 0 | AN10: 0 | AO10: 4 | AP10: 0 | AQ10: 0 | AR10: 0 | AS10: 0 | AT10: =SUM(B10:AS10) -> 16596 | AU10: =model!AT10 -> 24539
A11: Bonneville County | B11: 66 | C11: 0 | D11: 280 | E11: 0 | F11: 0 | G11: 1549 | H11: 0 | I11: 0 | J11: 0 | K11: 45398 | L11: 0 | M11: 1006 | N11: 0 | O11: 3 | P11: 12 | Q11: 73 | R11: 0 | S11: 0 | T11: 0 | U11: 0 | V11: 0 | W11: 139 | X11: 0 | Y11: 0 | Z11: 0 | AA11: 1640 | AB11: 0 | AC11: 0 | AD11: 0 | AE11: 0 | AF11: 0 | AG11: 0 | AH11: 1025 | AI11: 0 | AJ11: 0 | AK11: 0 | AL11: 0 | AM11: 0 | AN11: 0 | AO11: 0 | AP11: 90 | AQ11: 93 | AR11: 0 | AS11: 0 | AT11: =SUM(B11:AS11) -> 51374 | AU11: =model!AT11 -> 37185
A12: Boundary County | B12: 0 | C12: 0 | D12: 0 | E12: 0 | F12: 0 | G12: 0 | H12: 0 | I12: 0 | J12: 345 | K12: 0 | L12: 4067 | M12: 0 | N12: 0 | O12: 0 | P12: 0 | Q12: 0 | R12: 0 | S12: 0 | T12: 0 | U12: 0 | V12: 0 | W12: 0 | X12: 0 | Y12: 0 | Z12: 0 | AA12: 0 | AB12: 0 | AC12: 114 | AD12: 0 | AE12: 0 | AF12: 0 | AG12: 0 | AH12: 0 | AI12: 0 | AJ12: 0 | AK12: 0 | AL12: 0 | AM12: 0 | AN12: 0 | AO12: 0 | AP12: 0 | AQ12: 0 | AR12: 0 | AS12: 0 | AT12: =SUM(B12:AS12) -> 4526 | AU12: =model!AT12 -> 6355
A13: Butte County | B13: 0 | C13: 0 | D13: 5 | E13: 0 | F13: 0 | G13: 4 | H13: 0 | I13: 0 | J13: 0 | K13: 122 | L13: 0 | M13: 871 | N13: 0 | O13: 0 | P13: 0 | Q13: 0 | R13: 0 | S13: 0 | T13: 12 | U13: 0 | V13: 0 | W13: 0 | X13: 0 | Y13: 0 | Z13: 0 | AA13: 0 | AB13: 0 | AC13: 0 | AD13: 0 | AE13: 0 | AF13: 0 | AG13: 0 | AH13: 0 | AI13: 0 | AJ13: 0 | AK13: 0 | AL13: 0 | AM13: 0 | AN13: 0 | AO13: 0 | AP13: 0 | AQ13: 0 | AR13: 0 | AS13: 0 | AT13: =SUM(B13:AS13) -> 1014 | AU13: =model!AT13 -> 1448
... A45: Washington County | B45: 178 | C45: 17 | D45: 0 | E45: 0 | F45: 0 | G45: 0 | H45: 0 | I45: 0 | J45: 0 | K45: 0 | L45: 0 | M45: 0 | N45: 0 | O45: 80 | P45: 0 | Q45: 0 | R45: 0 | S45: 0 | T45: 0 | U45: 0 | V45: 0 | W45: 0 | X45: 14 | Y45: 0 | Z45: 0 | AA45: 0 | AB45: 0 | AC45: 0 | AD45: 0 | AE45: 0 | AF45: 0 | AG45: 0 | AH45: 0 | AI45: 0 | AJ45: 0 | AK45: 0 | AL45: 0 | AM45: 125 | AN45: 0 | AO45: 0 | AP45: 0 | AQ45: 0 | AR45: 0 | AS45: 2661 | AT45: =SUM(B45:AS45) -> 3075 | AU45: =model!AT45 -> 5477
A46: ACS Total | B46: =SUM(B2:B45) -> 260709 | C46: =SUM(C2:C45) -> 997 | D46: =SUM(D2:D45) -> 34195 | E46: =SUM(E2:E45) -> 1749 | F46: =SUM(F2:F45) -> 3689 | G46: =SUM(G2:G45) -> 15599 | H46: =SUM(H2:H45) -> 13427 | I46: =SUM(I2:I45) -> 2327 | ... AS46: =SUM(AS2:AS45) -> 3033
A47: Model Total | B47: =model!B46 -> 318899 | C47: =model!C46 -> 2213 | D47: =model!D46 -> 49379 | E47: =model!E46 -> 2573 | F47: =model!F46 -> 3502 | G47: =model!G46 -> 15093 | H47: =model!H46 -> 14867 | I47: =model!I46 -> 2245 | ... AS47: =model!AS46 -> 3832
A50: Iter 1R | B50: Ada County | C50: Adams County | D50: Bannock County | E50: Bear Lake County | F50: Benewah County | G50: Bingham County | H50: Blaine County | I50: Boise County | J50: Bonner County | K50: Bonneville County | L50: Boundary County | M50: Butte County | N50: Camas County | O50: Canyon County | P50: Caribou County | Q50: Cassia County | R50: Clark County | S50: Clearwater County | T50: Custer County | U50: Elmore County | V50: Franklin County | W50: Fremont County | X50: Gem County | Y50: Gooding County | Z50: Idaho County | AA50: Jefferson County | AB50: Jerome County | AC50: Kootenai County | AD50: Latah County | AE50: Lemhi County | AF50: Lewis County | AG50: Lincoln County | AH50: Madison County | AI50: Minidoka County | AJ50: Nez Perce County | AK50: Oneida County | AL50: Owyhee County | AM50: Payette County | AN50: Power County | AO50: Shoshone County | AP50: Teton County | AQ50: Twin Falls County | AR50: Valley County | AS50: Washington County | AT50: ACS Total | AU50: Model Total
A51: Ada County | B51: =B2*($AU2/$AT2) -> 256592.28 | C51: =C2*($AU2/$AT2) -> 3.4832161 | D51: =D2*($AU2/$AT2) -> 17.416081 | E51: =E2*($AU2/$AT2) -> 0 | F51: =F2*($AU2/$AT2) -> 0 | G51: =G2*($AU2/$AT2) -> 0 | H51: =H2*($AU2/$AT2) -> 118.42935 | I51: =I2*($AU2/$AT2) -> 714.0593 | ... AS51: =AS2*($AU2/$AT2) -> 69.664322 | AT51: =SUM(B51:AS51) -> 274359 | AU51: =model!AT2 -> 274359
A52: Adams County | B52: =B3*($AU3/$AT3) -> 6.4813115 | C52: =C3*($AU3/$AT3) -> 1437.2308 | D52: =D3*($AU3/$AT3) -> 0 | E52: =E3*($AU3/$AT3) -> 0 | F52: =F3*($AU3/$AT3) -> 0 | G52: =G3*($AU3/$AT3) -> 0 | H52: =H3*($AU3/$AT3) -> 0 | I52: =I3*($AU3/$AT3) -> 0 | ... AS52: =AS3*($AU3/$AT3) -> 19.443934 | AT52: =SUM(B52:AS52) -> 2471 | AU52: =model!AT3 -> 2471
A53: Bannock County | B53: =B4*($AU4/$AT4) -> 35.134259 | C53: =C4*($AU4/$AT4) -> 0 | D53: =D4*($AU4/$AT4) -> 44381.596 | E53: =E4*($AU4/$AT4) -> 0 | F53: =F4*($AU4/$AT4) -> 0 | G53: =G4*($AU4/$AT4) -> 1724.3895 | H53: =H4*($AU4/$AT4) -> 0 | I53: =I4*($AU4/$AT4) -> 0 | ... AS53: =AS4*($AU4/$AT4) -> 0 | AT53: =SUM(B53:AS53) -> 49878 | AU53: =model!AT4 -> 49878
A54: Bear Lake County | B54: =B5*($AU5/$AT5) -> 22.011013 | C54: =C5*($AU5/$AT5) -> 0 | D54: =D5*($AU5/$AT5) -> 44.022026 | E54: =E5*($AU5/$AT5) -> 2431.4833 | F54: =F5*($AU5/$AT5) -> 0 | G54: =G5*($AU5/$AT5) -> 1.4674009 | H54: =H5*($AU5/$AT5) -> 0 | I54: =I5*($AU5/$AT5) -> 0 | ... AS54: =AS5*($AU5/$AT5) -> 0 | AT54: =SUM(B54:AS54) -> 3331 | AU54: =model!AT5 -> 3331
A55: Benewah County | B55: =B6*($AU6/$AT6) -> 0 | C55: =C6*($AU6/$AT6) -> 0 | D55: =D6*($AU6/$AT6) -> 0 | E55: =E6*($AU6/$AT6) -> 0 | F55: =F6*($AU6/$AT6) -> 3924.2573 | G55: =G6*($AU6/$AT6) -> 0 | H55: =H6*($AU6/$AT6) -> 0 | I55: =I6*($AU6/$AT6) -> 0 | ... AS55: =AS6*($AU6/$AT6) -> 0 | AT55: =SUM(B55:AS55) -> 4939 | AU55: =model!AT6 -> 4939
A56: Bingham County | B56: =B7*($AU7/$AT7) -> 0 | C56: =C7*($AU7/$AT7) -> 0 | D56: =D7*($AU7/$AT7) -> 1436.293 | E56: =E7*($AU7/$AT7) -> 0 | F56: =F7*($AU7/$AT7) -> 0 | G56: =G7*($AU7/$AT7) -> 16285.496 | H56: =H7*($AU7/$AT7) -> 0 | I56: =I7*($AU7/$AT7) -> 0 | ... AS56: =AS7*($AU7/$AT7) -> 0 | AT56: =SUM(B56:AS56) -> 25685 | AU56: =model!AT7 -> 25685
A57: Blaine County | B57: =B8*($AU8/$AT8) -> 0 | C57: =C8*($AU8/$AT8) -> 0 | D57: =D8*($AU8/$AT8) -> 0 | E57: =E8*($AU8/$AT8) -> 0 | F57: =F8*($AU8/$AT8) -> 0 | G57: =G8*($AU8/$AT8) -> 0 | H57: =H8*($AU8/$AT8) -> 13669.905 | I57: =I8*($AU8/$AT8) -> 0 | ... AS57: =AS8*($AU8/$AT8) -> 0 | AT57: =SUM(B57:AS57) -> 13880 | AU57: =model!AT8 -> 13880
A58: Boise County | B58: =B9*($AU9/$AT9) -> 2167.9512 | C58: =C9*($AU9/$AT9) -> 0 | D58: =D9*($AU9/$AT9) -> 0 | E58: =E9*($AU9/$AT9) -> 0 | F58: =F9*($AU9/$AT9) -> 0 | G58: =G9*($AU9/$AT9) -> 0 | H58: =H9*($AU9/$AT9) -> 0 | I58: =I9*($AU9/$AT9) -> 2191.381 | ... AS58: =AS9*($AU9/$AT9) -> 0 | AT58: =SUM(B58:AS58) -> 4431 | AU58: =model!AT9 -> 4431
A59: Bonner County | B59: =B10*($AU10/$AT10) -> 0 | C59: =C10*($AU10/$AT10) -> 0 | D59: =D10*($AU10/$AT10) -> 0 | E59: =E10*($AU10/$AT10) -> 0 | F59: =F10*($AU10/$AT10) -> 0 | G59: =G10*($AU10/$AT10) -> 0 | H59: =H10*($AU10/$AT10) -> 0 | I59: =I10*($AU10/$AT10) -> 0 | ... AS59: =AS10*($AU10/$AT10) -> 0 | AT59: =SUM(B59:AS59) -> 24539 | AU59: =model!AT10 -> 24539
A60: Bonneville County | B60: =B11*($AU11/$AT11) -> 47.771441 | C60: =C11*($AU11/$AT11) -> 0 | D60: =D11*($AU11/$AT11) -> 202.66672 | E60: =E11*($AU11/$AT11) -> 0 | F60: =F11*($AU11/$AT11) -> 0 | G60: =G11*($AU11/$AT11) -> 1121.1812 | H60: =H11*($AU11/$AT11) -> 0 | I60: =I11*($AU11/$AT11) -> 0 | ... AS60: =AS11*($AU11/$AT11) -> 0 | AT60: =SUM(B60:AS60) -> 37185 | AU60: =model!AT11 -> 37185
A61: Boundary County | B61: =B12*($AU12/$AT12) -> 0 | C61: =C12*($AU12/$AT12) -> 0 | D61: =D12*($AU12/$AT12) -> 0 | E61: =E12*($AU12/$AT12) -> 0 | F61: =F12*($AU12/$AT12) -> 0 | G61: =G12*($AU12/$AT12) -> 0 | H61: =H12*($AU12/$AT12) -> 0 | I61: =I12*($AU12/$AT12) -> 0 | ... AS61: =AS12*($AU12/$AT12) -> 0 | AT61: =SUM(B61:AS61) -> 6355 | AU61: =model!AT12 -> 6355
A62: Butte County | B62: =B13*($AU13/$AT13) -> 0 | C62: =C13*($AU13/$AT13) -> 0 | D62: =D13*($AU13/$AT13) -> 7.1400394 | E62: =E13*($AU13/$AT13) -> 0 | F62: =F13*($AU13/$AT13) -> 0 | G62: =G13*($AU13/$AT13) -> 5.7120316 | H62: =H13*($AU13/$AT13) -> 0 | I62: =I13*($AU13/$AT13) -> 0 | ... AS62: =AS13*($AU13/$AT13) -> 0 | AT62: =SUM(B62:AS62) -> 1448 | AU62: =model!AT13 -> 1448
... A94: Washington County | B94: =B45*($AU45/$AT45) -> 317.0426 | C94: =C45*($AU45/$AT45) -> 30.27935 | D94: =D45*($AU45/$AT45) -> 0 | E94: =E45*($AU45/$AT45) -> 0 | F94: =F45*($AU45/$AT45) -> 0 | G94: =G45*($AU45/$AT45) -> 0 | H94: =H45*($AU45/$AT45) -> 0 | I94: =I45*($AU45/$AT45) -> 0 | ... AS94: =AS45*($AU45/$AT45) -> 4739.6088 | AT94: =SUM(B94:AS94) -> 5477 | AU94: =model!AT45 -> 5477
A95: ACS Total | B95: =SUM(B51:B94) -> 308336.16 | C95: =SUM(C51:C94) -> 1595.4056 | D95: =SUM(D51:D94) -> 47625.378 | E95: =SUM(E51:E94) -> 2549.0304 | F95: =SUM(F51:F94) -> 5500.8203 | G95: =SUM(G51:G94) -> 19831.791 | H95: =SUM(H51:H94) -> 15631.597 | I95: =SUM(I51:I94) -> 3076.8614 | ... AS95: =SUM(AS51:AS94) -> 5311.4963
A96: Model Total | B96: =model!B46 -> 318899 | C96: =model!C46 -> 2213 | D96: =model!D46 -> 49379 | E96: =model!E46 -> 2573 | F96: =model!F46 -> 3502 | G96: =model!G46 -> 15093 | H96: =model!H46 -> 14867 | I96: =model!I46 -> 2245 | ... AS96: =model!AS46 -> 3832
A99: Iter 1C | B99: Ada County | C99: Adams County | D99: Bannock County | E99: Bear Lake County | F99: Benewah County | G99: Bingham County | H99: Blaine County | I99: Boise County | J99: Bonner County | K99: Bonneville County | L99: Boundary County | M99: Butte County | N99: Camas County | O99: Canyon County | P99: Caribou County | Q99: Cassia County | R99: Clark County | S99: Clearwater County | T99: Custer County | U99: Elmore County | V99: Franklin County | W99: Fremont County | X99: Gem County | Y99: Gooding County | Z99: Idaho County | AA99: Jefferson County | AB99: Jerome County | AC99: Kootenai County | AD99: Latah County | AE99: Lemhi County | AF99: Lewis County | AG99: Lincoln County | AH99: Madison County | AI99: Minidoka County | AJ99: Nez Perce County | AK99: Oneida County | AL99: Owyhee County | AM99: Payette County | AN99: Power County | AO99: Shoshone County | AP99: Teton County | AQ99: Twin Falls County | AR99: Valley County | AS99: Washington County | AT99: ACS Total | AU99: Model Total
A100: Ada County | B100: =B51*(B$96/B$95) -> 265382.49 | C100: =C51*(C$96/C$95) -> 4.8315973 | D100: =D51*(D$96/D$95) -> 18.057361 | E100: =E51*(E$96/E$95) -> 0 | F100: =F51*(F$96/F$95) -> 0 | G100: =G51*(G$96/G$95) -> 0 | H100: =H51*(H$96/H$95) -> 112.63655 | I100: =I51*(I$96/I$95) -> 521.00596 | ... AS100: =AS51*(AS$96/AS$95) -> 50.259601 | AT100: =SUM(B100:AS100) -> 282950.41 | AU100: =model!AT2 -> 274359
A101: Adams County | B101: =B52*(B$96/B$95) -> 6.7033452 | C101: =C52*(C$96/C$95) -> 1993.5945 | D101: =D52*(D$96/D$95) -> 0 | E101: =E52*(E$96/E$95) -> 0 | F101: =F52*(F$96/F$95) -> 0 | G101: =G52*(G$96/G$95) -> 0 | H101: =H52*(H$96/H$95) -> 0 | I101: =I52*(I$96/I$95) -> 0 | ... AS101: =AS52*(AS$96/AS$95) -> 14.027903 | AT101: =SUM(B101:AS101) -> 2823.4771 | AU101: =model!AT3 -> 2471
A102: Bannock County | B102: =B53*(B$96/B$95) -> 36.337872 | C102: =C53*(C$96/C$95) -> 0 | D102: =D53*(D$96/D$95) -> 46015.779 | E102: =E53*(E$96/E$95) -> 0 | F102: =F53*(F$96/F$95) -> 0 | G102: =G53*(G$96/G$95) -> 1312.3479 | H102: =H53*(H$96/H$95) -> 0 | I102: =I53*(I$96/I$95) -> 0 | ... AS102: =AS53*(AS$96/AS$95) -> 0 | AT102: =SUM(B102:AS102) -> 50780.874 | AU102: =model!AT4 -> 49878
A103: Bear Lake County | B103: =B54*(B$96/B$95) -> 22.765056 | C103: =C54*(C$96/C$95) -> 0 | D103: =D54*(D$96/D$95) -> 45.642969 | E103: =E54*(E$96/E$95) -> 2454.3475 | F103: =F54*(F$96/F$95) -> 0 | G103: =G54*(G$96/G$95) -> 1.1167666 | H103: =H54*(H$96/H$95) -> 0 | I103: =I54*(I$96/I$95) -> 0 | ... AS103: =AS54*(AS$96/AS$95) -> 0 | AT103: =SUM(B103:AS103) -> 3046.4647 | AU103: =model!AT5 -> 3331
A104: Benewah County | B104: =B55*(B$96/B$95) -> 0 | C104: =C55*(C$96/C$95) -> 0 | D104: =D55*(D$96/D$95) -> 0 | E104: =E55*(E$96/E$95) -> 0 | F104: =F55*(F$96/F$95) -> 2498.3091 | G104: =G55*(G$96/G$95) -> 0 | H104: =H55*(H$96/H$95) -> 0 | I104: =I55*(I$96/I$95) -> 0 | ... AS104: =AS55*(AS$96/AS$95) -> 0 | AT104: =SUM(B104:AS104) -> 3622.1487 | AU104: =model!AT6 -> 4939
A105: Bingham County | B105: =B56*(B$96/B$95) -> 0 | C105: =C56*(C$96/C$95) -> 0 | D105: =D56*(D$96/D$95) -> 1489.179 | E105: =E56*(E$96/E$95) -> 0 | F105: =F56*(F$96/F$95) -> 0 | G105: =G56*(G$96/G$95) -> 12394.089 | H105: =H56*(H$96/H$95) -> 0 | I105: =I56*(I$96/I$95) -> 0 | ... AS105: =AS56*(AS$96/AS$95) -> 0 | AT105: =SUM(B105:AS105) -> 27855.321 | AU105: =model!AT7 -> 25685
A106: Blaine County | B106: =B57*(B$96/B$95) -> 0 | C106: =C57*(C$96/C$95) -> 0 | D106: =D57*(D$96/D$95) -> 0 | E106: =E57*(E$96/E$95) -> 0 | F106: =F57*(F$96/F$95) -> 0 | G106: =G57*(G$96/G$95) -> 0 | H106: =H57*(H$96/H$95) -> 13001.261 | I106: =I57*(I$96/I$95) -> 0 | ... AS106: =AS57*(AS$96/AS$95) -> 0 | AT106: =SUM(B106:AS106) -> 13160.505 | AU106: =model!AT8 -> 13880
...

Sheet Obs IPF
A1: ='IPF ACS to ASIM'!A834 -> Iter 9R | B1: ='IPF ACS to ASIM'!B834 -> Ada County | C1: ='IPF ACS to ASIM'!C834 -> Adams County | D1: ='IPF ACS to ASIM'!D834 -> Bannock County | E1: ='IPF ACS to ASIM'!E834 -> Bear Lake County | F1: ='IPF ACS to ASIM'!F834 -> Benewah County | G1: ='IPF ACS to ASIM'!G834 -> Bingham County | H1: ='IPF ACS to ASIM'!H834 -> Blaine County | ... AU1: ='IPF ACS to ASIM'!AU834 -> Model Total
A2: ='IPF ACS to ASIM'!A835 -> Ada County | B2: ='IPF ACS to ASIM'!B835 -> 258551.97 | C2: ='IPF ACS to ASIM'!C835 -> 3.462906 | D2: ='IPF ACS to ASIM'!D835 -> 21.329576 | E2: ='IPF ACS to ASIM'!E835 -> 0 | F2: ='IPF ACS to ASIM'!F835 -> 0 | G2: ='IPF ACS to ASIM'!G835 -> 0 | H2: ='IPF ACS to ASIM'!H835 -> 53.267954 | ... AU2: ='IPF ACS to ASIM'!AU835 -> 274359
A3: ='IPF ACS to ASIM'!A836 -> Adams County | B3: ='IPF ACS to ASIM'!B836 -> 9.1761609 | C3: ='IPF ACS to ASIM'!C836 -> 2007.616 | D3: ='IPF ACS to ASIM'!D836 -> 0 | E3: ='IPF ACS to ASIM'!E836 -> 0 | F3: ='IPF ACS to ASIM'!F836 -> 0 | G3: ='IPF ACS to ASIM'!G836 -> 0 | H3: ='IPF ACS to ASIM'!H836 -> 0 | ... AU3: ='IPF ACS to ASIM'!AU836 -> 2471
A4: ='IPF ACS to ASIM'!A837 -> Bannock County | B4: ='IPF ACS to ASIM'!B837 -> 26.737197 | C4: ='IPF ACS to ASIM'!C837 -> 0 | D4: ='IPF ACS to ASIM'!D837 -> 41050.222 | E4: ='IPF ACS to ASIM'!E837 -> 0 | F4: ='IPF ACS to ASIM'!F837 -> 0 | G4: ='IPF ACS to ASIM'!G837 -> 2371.1965 | H4: ='IPF ACS to ASIM'!H837 -> 0 | ... AU4: ='IPF ACS to ASIM'!AU837 -> 49878
A5: ='IPF ACS to ASIM'!A838 -> Bear Lake County | B5: ='IPF ACS to ASIM'!B838 -> 67.829047 | C5: ='IPF ACS to ASIM'!C838 -> 0 | D5: ='IPF ACS to ASIM'!D838 -> 164.88199 | E5: ='IPF ACS to ASIM'!E838 -> 2638.801 | F5: ='IPF ACS to ASIM'!F838 -> 0 | G5: ='IPF ACS to ASIM'!G838 -> 8.1709313 | H5: ='IPF ACS to ASIM'!H838 -> 0 | ... AU5: ='IPF ACS to ASIM'!AU838 -> 3331
A6: ='IPF ACS to ASIM'!A839 -> Benewah County | B6: ='IPF ACS to ASIM'!B839 -> 0 | C6: ='IPF ACS to ASIM'!C839 -> 0 | D6: ='IPF ACS to ASIM'!D839 -> 0 | E6: ='IPF ACS to ASIM'!E839 -> 0 | F6: ='IPF ACS to ASIM'!F839 -> 2800.5388 | G6: ='IPF ACS to ASIM'!G839 -> 0 | H6: ='IPF ACS to ASIM'!H839 -> 0 | ... AU6: ='IPF ACS to ASIM'!AU839 -> 4939
A7: ='IPF ACS to ASIM'!A840 -> Bingham County | B7: ='IPF ACS to ASIM'!B840 -> 0 | C7: ='IPF ACS to ASIM'!C840 -> 0 | D7: ='IPF ACS to ASIM'!D840 -> 545.32446 | E7: ='IPF ACS to ASIM'!E840 -> 0 | F7: ='IPF ACS to ASIM'!F840 -> 0 | G7: ='IPF ACS to ASIM'!G840 -> 9192.4758 | H7: ='IPF ACS to ASIM'!H840 -> 0 | ... AU7: ='IPF ACS to ASIM'!AU840 -> 25685
A8: ='IPF ACS to ASIM'!A841 -> Blaine County | B8: ='IPF ACS to ASIM'!B841 -> 0 | C8: ='IPF ACS to ASIM'!C841 -> 0 | D8: ='IPF ACS to ASIM'!D841 -> 0 | E8: ='IPF ACS to ASIM'!E841 -> 0 | F8: ='IPF ACS to ASIM'!F841 -> 0 | G8: ='IPF ACS to ASIM'!G841 -> 0 | H8: ='IPF ACS to ASIM'!H841 -> 13754.394 | ... AU8: ='IPF ACS to ASIM'!AU841 -> 13880
A9: ='IPF ACS to ASIM'!A842 -> Boise County | B9: ='IPF ACS to ASIM'!B842 -> 2686.0898 | C9: ='IPF ACS to ASIM'!C842 -> 0 | D9: ='IPF ACS to ASIM'!D842 -> 0 | E9: ='IPF ACS to ASIM'!E842 -> 0 | F9: ='IPF ACS to ASIM'!F842 -> 0 | G9: ='IPF ACS to ASIM'!G842 -> 0 | H9: ='IPF ACS to ASIM'!H842 -> 0 | ... AU9: ='IPF ACS to ASIM'!AU842 -> 4431
A10: ='IPF ACS to ASIM'!A843 -> Bonner County | B10: ='IPF ACS to ASIM'!B843 -> 0 | C10: ='IPF ACS to ASIM'!C843 -> 0 | D10: ='IPF ACS to ASIM'!D843 -> 0 | E10: ='IPF ACS to ASIM'!E843 -> 0 | F10: ='IPF ACS to ASIM'!F843 -> 0 | G10: ='IPF ACS to ASIM'!G843 -> 0 | H10: ='IPF ACS to ASIM'!H843 -> 0 | ... AU10: ='IPF ACS to ASIM'!AU843 -> 24539
A11: ='IPF ACS to ASIM'!A844 -> Bonneville County | B11: ='IPF ACS to ASIM'!B844 -> 6.7947204 | C11: ='IPF ACS to ASIM'!C844 -> 0 | D11: ='IPF ACS to ASIM'!D844 -> 35.035894 | E11: ='IPF ACS to ASIM'!E844 -> 0 | F11: ='IPF ACS to ASIM'!F844 -> 0 | G11: ='IPF ACS to ASIM'!G844 -> 288.15501 | H11: ='IPF ACS to ASIM'!H844 -> 0 | ... AU11: ='IPF ACS to ASIM'!AU844 -> 37185
A12: ='IPF ACS to ASIM'!A845 -> Boundary County | B12: ='IPF ACS to ASIM'!B845 -> 0 | C12: ='IPF ACS to ASIM'!C845 -> 0 | D12: ='IPF ACS to ASIM'!D845 -> 0 | E12: ='IPF ACS to ASIM'!E845 -> 0 | F12: ='IPF ACS to ASIM'!F845 -> 0 | G12: ='IPF ACS to ASIM'!G845 -> 0 | H12: ='IPF ACS to ASIM'!H845 -> 0 | ... AU12: ='IPF ACS to ASIM'!AU845 -> 6355
... A45: ='IPF ACS to ASIM'!A878 -> Washington County | B45: ='IPF ACS to ASIM'!B878 -> 999.28257 | C45: ='IPF ACS to ASIM'!C878 -> 94.161471 | D45: ='IPF ACS to ASIM'!D878 -> 0 | E45: ='IPF ACS to ASIM'!E878 -> 0 | F45: ='IPF ACS to ASIM'!F878 -> 0 | G45: ='IPF ACS to ASIM'!G878 -> 0 | H45: ='IPF ACS to ASIM'!H878 -> 0 | ... AU45: ='IPF ACS to ASIM'!AU878 -> 5477
A46: ='IPF ACS to ASIM'!A879 -> ACS Total | B46: ='IPF ACS to ASIM'!B879 -> 319285.77 | C46: ='IPF ACS to ASIM'!C879 -> 2384.0944 | D46: ='IPF ACS to ASIM'!D879 -> 46491.601 | E46: ='IPF ACS to ASIM'!E879 -> 2799.0769 | F46: ='IPF ACS to ASIM'!F879 -> 3412.8602 | G46: ='IPF ACS to ASIM'!G879 -> 13913.62 | H46: ='IPF ACS to ASIM'!H879 -> 16801.644 | ... AS46: ='IPF ACS to ASIM'!AS879 -> 3932.4899 | AT46: =SUM(B46:AS46) -> 972431
A47: ='IPF ACS to ASIM'!A880 -> Model Total | B47: ='IPF ACS to ASIM'!B880 -> 318899 | C47: ='IPF ACS to ASIM'!C880 -> 2213 | D47: ='IPF ACS to ASIM'!D880 -> 49379 | E47: ='IPF ACS to ASIM'!E880 -> 2573 | F47: ='IPF ACS to ASIM'!F880 -> 3502 | G47: ='IPF ACS to ASIM'!G880 -> 15093 | H47: ='IPF ACS to ASIM'!H880 -> 14867 | ... AS47: ='IPF ACS to ASIM'!AS880 -> 3832 | AU47: =SUM(B47:AS47) -> 972431

Sheet Difference (obs IPF-model)
B1: ='IPF ACS to ASIM'!B834 -> Ada County | C1: ='IPF ACS to ASIM'!C834 -> Adams County | D1: ='IPF ACS to ASIM'!D834 -> Bannock County | E1: ='IPF ACS to ASIM'!E834 -> Bear Lake County | F1: ='IPF ACS to ASIM'!F834 -> Benewah County | G1: ='IPF ACS to ASIM'!G834 -> Bingham County | H1: ='IPF ACS to ASIM'!H834 -> Blaine County | I1: ='IPF ACS to ASIM'!I834 -> Boise County | ... AS1: ='IPF ACS to ASIM'!AS834 -> Washington County | AT1: Total
A2: ='IPF ACS to ASIM'!A835 -> Ada County | B2: ='Obs IPF'!B2-model!B2 -> -1698.029 | C2: ='Obs IPF'!C2-model!C2 -> 2.462906 | D2: ='Obs IPF'!D2-model!D2 -> -45.670424 | E2: ='Obs IPF'!E2-model!E2 -> 0 | F2: ='Obs IPF'!F2-model!F2 -> 0 | G2: ='Obs IPF'!G2-model!G2 -> -8 | H2: ='Obs IPF'!H2-model!H2 -> -0.73204602 | I2: ='Obs IPF'!I2-model!I2 -> 417.37783 | ... AT2: ='Obs IPF'!AT2-model!AT2 -> 0
A3: ='IPF ACS to ASIM'!A836 -> Adams County | B3: ='Obs IPF'!B3-model!B3 -> -116.82384 | C3: ='Obs IPF'!C3-model!C3 -> -170.38397 | D3: ='Obs IPF'!D3-model!D3 -> 0 | E3: ='Obs IPF'!E3-model!E3 -> 0 | F3: ='Obs IPF'!F3-model!F3 -> 0 | G3: ='Obs IPF'!G3-model!G3 -> 0 | H3: ='Obs IPF'!H3-model!H3 -> 0 | I3: ='Obs IPF'!I3-model!I3 -> 0 | ... AT3: ='Obs IPF'!AT3-model!AT3 -> 0
A4: ='IPF ACS to ASIM'!A837 -> Bannock County | B4: ='Obs IPF'!B4-model!B4 -> 17.737197 | C4: ='Obs IPF'!C4-model!C4 -> 0 | D4: ='Obs IPF'!D4-model!D4 -> 5426.2224 | E4: ='Obs IPF'!E4-model!E4 -> -1 | F4: ='Obs IPF'!F4-model!F4 -> 0 | G4: ='Obs IPF'!G4-model!G4 -> 1588.1965 | H4: ='Obs IPF'!H4-model!H4 -> -9 | I4: ='Obs IPF'!I4-model!I4 -> 0 | ... AT4: ='Obs IPF'!AT4-model!AT4 -> 0
A5: ='IPF ACS to ASIM'!A838 -> Bear Lake County | B5: ='Obs IPF'!B5-model!B5 -> 65.829047 | C5: ='Obs IPF'!C5-model!C5 -> 0 | D5: ='Obs IPF'!D5-model!D5 -> -48.118007 | E5: ='Obs IPF'!E5-model!E5 -> 78.800976 | F5: ='Obs IPF'!F5-model!F5 -> 0 | G5: ='Obs IPF'!G5-model!G5 -> -17.829069 | H5: ='Obs IPF'!H5-model!H5 -> 0 | I5: ='Obs IPF'!I5-model!I5 -> 0 | ... AT5: ='Obs IPF'!AT5-model!AT5 -> 0
A6: ='IPF ACS to ASIM'!A839 -> Benewah County | B6: ='Obs IPF'!B6-model!B6 -> 0 | C6: ='Obs IPF'!C6-model!C6 -> 0 | D6: ='Obs IPF'!D6-model!D6 -> 0 | E6: ='Obs IPF'!E6-model!E6 -> 0 | F6: ='Obs IPF'!F6-model!F6 -> -284.46119 | G6: ='Obs IPF'!G6-model!G6 -> 0 | H6: ='Obs IPF'!H6-model!H6 -> 0 | I6: ='Obs IPF'!I6-model!I6 -> 0 | ... AT6: ='Obs IPF'!AT6-model!AT6 -> 0
A7: ='IPF ACS to ASIM'!A840 -> Bingham County | B7: ='Obs IPF'!B7-model!B7 -> 0 | C7: ='Obs IPF'!C7-model!C7 -> 0 | D7: ='Obs IPF'!D7-model!D7 -> -1151.6755 | E7: ='Obs IPF'!E7-model!E7 -> 0 | F7: ='Obs IPF'!F7-model!F7 -> 0 | G7: ='Obs IPF'!G7-model!G7 -> -3524.5242 | H7: ='Obs IPF'!H7-model!H7 -> -5 | I7: ='Obs IPF'!I7-model!I7 -> 0 | ... AT7: ='Obs IPF'!AT7-model!AT7 -> 0
A8: ='IPF ACS to ASIM'!A841 -> Blaine County | B8: ='Obs IPF'!B8-model!B8 -> -17 | C8: ='Obs IPF'!C8-model!C8 -> 0 | D8: ='Obs IPF'!D8-model!D8 -> -36 | E8: ='Obs IPF'!E8-model!E8 -> 0 | F8: ='Obs IPF'!F8-model!F8 -> 0 | G8: ='Obs IPF'!G8-model!G8 -> -19 | H8: ='Obs IPF'!H8-model!H8 -> 519.39381 | I8: ='Obs IPF'!I8-model!I8 -> 0 | ... AT8: ='Obs IPF'!AT8-model!AT8 -> 0
A9: ='IPF ACS to ASIM'!A842 -> Boise County | B9: ='Obs IPF'!B9-model!B9 -> 939.08985 | C9: ='Obs IPF'!C9-model!C9 -> 0 | D9: ='Obs IPF'!D9-model!D9 -> -5 | E9: ='Obs IPF'!E9-model!E9 -> 0 | F9: ='Obs IPF'!F9-model!F9 -> 0 | G9: ='Obs IPF'!G9-model!G9 -> 0 | H9: ='Obs IPF'!H9-model!H9 -> -4 | I9: ='Obs IPF'!I9-model!I9 -> -484.11698 | ... AT9: ='Obs IPF'!AT9-model!AT9 -> 0
A10: ='IPF ACS to ASIM'!A843 -> Bonner County | B10: ='Obs IPF'!B10-model!B10 -> 0 | C10: ='Obs IPF'!C10-model!C10 -> 0 | D10: ='Obs IPF'!D10-model!D10 -> 0 | E10: ='Obs IPF'!E10-model!E10 -> 0 | F10: ='Obs IPF'!F10-model!F10 -> -40 | G10: ='Obs IPF'!G10-model!G10 -> 0 | H10: ='Obs IPF'!H10-model!H10 -> 0 | I10: ='Obs IPF'!I10-model!I10 -> 0 | ... AT10: ='Obs IPF'!AT10-model!AT10 -> 0
A11: ='IPF ACS to ASIM'!A844 -> Bonneville County | B11: ='Obs IPF'!B11-model!B11 -> 4.7947204 | C11: ='Obs IPF'!C11-model!C11 -> 0 | D11: ='Obs IPF'!D11-model!D11 -> -550.96411 | E11: ='Obs IPF'!E11-model!E11 -> 0 | F11: ='Obs IPF'!F11-model!F11 -> 0 | G11: ='Obs IPF'!G11-model!G11 -> 63.155014 | H11: ='Obs IPF'!H11-model!H11 -> 0 | I11: ='Obs IPF'!I11-model!I11 -> 0 | ... AT11: ='Obs IPF'!AT11-model!AT11 -> 0
A12: ='IPF ACS to ASIM'!A845 -> Boundary County | B12: ='Obs IPF'!B12-model!B12 -> 0 | C12: ='Obs IPF'!C12-model!C12 -> 0 | D12: ='Obs IPF'!D12-model!D12 -> 0 | E12: ='Obs IPF'!E12-model!E12 -> 0 | F12: ='Obs IPF'!F12-model!F12 -> -21 | G12: ='Obs IPF'!G12-model!G12 -> 0 | H12: ='Obs IPF'!H12-model!H12 -> 0 | I12: ='Obs IPF'!I12-model!I12 -> 0 | ... AT12: ='Obs IPF'!AT12-model!AT12 -> 0
A13: ='IPF ACS to ASIM'!A846 -> Butte County | B13: ='Obs IPF'!B13-model!B13 -> -4 | C13: ='Obs IPF'!C13-model!C13 -> 0 | D13: ='Obs IPF'!D13-model!D13 -> -74.676341 | E13: ='Obs IPF'!E13-model!E13 -> 0 | F13: ='Obs IPF'!F13-model!F13 -> 0 | G13: ='Obs IPF'!G13-model!G13 -> -20.289608 | H13: ='Obs IPF'!H13-model!H13 -> -11 | I13: ='Obs IPF'!I13-model!I13 -> 0 | ... AT13: ='Obs IPF'!AT13-model!AT13 -> 0
... A45: ='IPF ACS to ASIM'!A878 -> Washington County | B45: ='Obs IPF'!B45-model!B45 -> -52.717433 | C45: ='Obs IPF'!C45-model!C45 -> 89.161471 | D45: ='Obs IPF'!D45-model!D45 -> -1 | E45: ='Obs IPF'!E45-model!E45 -> 0 | F45: ='Obs IPF'!F45-model!F45 -> 0 | G45: ='Obs IPF'!G45-model!G45 -> 0 | H45: ='Obs IPF'!H45-model!H45 -> -3 | I45: ='Obs IPF'!I45-model!I45 -> -2 | ... AT45: ='Obs IPF'!AT45-model!AT45 -> 0
A46: Total | B46: ='Obs IPF'!B46-model!B46 -> 386.76906 | C46: ='Obs IPF'!C46-model!C46 -> 171.09435 | D46: ='Obs IPF'!D46-model!D46 -> -2887.3994 | E46: ='Obs IPF'!E46-model!E46 -> 226.07689 | F46: ='Obs IPF'!F46-model!F46 -> -89.139783 | G46: ='Obs IPF'!G46-model!G46 -> -1179.3801 | H46: ='Obs IPF'!H46-model!H46 -> 1934.6439 | I46: ='Obs IPF'!I46-model!I46 -> -2.5058406 | ... AS46: ='Obs IPF'!AS46-model!AS46 -> 100.48993
A48: Observed Totals | B48: ='Obs IPF'!B46 -> 319285.77 | C48: ='Obs IPF'!C46 -> 2384.0944 | D48: ='Obs IPF'!D46 -> 46491.601 | E48: ='Obs IPF'!E46 -> 2799.0769 | F48: ='Obs IPF'!F46 -> 3412.8602 | G48: ='Obs IPF'!G46 -> 13913.62 | H48: ='Obs IPF'!H46 -> 16801.644 | I48: ='Obs IPF'!I46 -> 2242.4942 | ... AT48: ='Obs IPF'!AT46 -> 972431
A50: Percent Diff | B50: Ada County | C50: Adams County | D50: Bannock County | E50: Bear Lake County | F50: Benewah County | G50: Bingham County | H50: Blaine County | I50: Boise County | J50: Bonner County | K50: Bonneville County | L50: Boundary County | M50: Butte County | N50: Camas County | O50: Canyon County | P50: Caribou County | Q50: Cassia County | R50: Clark County | S50: Clearwater County | T50: Custer County | U50: Elmore County | V50: Franklin County | W50: Fremont County | X50: Gem County | Y50: Gooding County | Z50: Idaho County | AA50: Jefferson County | AB50: Jerome County | AC50: Kootenai County | AD50: Latah County | AE50: Lemhi County | AF50: Lewis County | AG50: Lincoln County | AH50: Madison County | AI50: Minidoka County | AJ50: Nez Perce County | AK50: Oneida County | AL50: Owyhee County | AM50: Payette County | AN50: Power County | AO50: Shoshone County | AP50: Teton County | AQ50: Twin Falls County | AR50: Valley County | AS50: Washington County | AT50: Total
A51: Ada County | B51: =IF('Obs IPF'!B2>0,B2/'Obs IPF'!B2,"") -> -0.0065674573 | C51: =IF('Obs IPF'!C2>0,C2/'Obs IPF'!C2,"") -> 0.71122519 | D51: =IF('Obs IPF'!D2>0,D2/'Obs IPF'!D2,"") -> -2.1411783 | E51: =IF('Obs IPF'!E2>0,E2/'Obs IPF'!E2,"") | F51: =IF('Obs IPF'!F2>0,F2/'Obs IPF'!F2,"") | G51: =IF('Obs IPF'!G2>0,G2/'Obs IPF'!G2,"") | H51: =IF('Obs IPF'!H2>0,H2/'Obs IPF'!H2,"") -> -0.01374271 | I51: =IF('Obs IPF'!I2>0,I2/'Obs IPF'!I2,"") -> 0.93924089 | ... AT51: =IF('Obs IPF'!AT2>0,AT2/'Obs IPF'!AT2,"") -> 0
A52: Adams County | B52: =IF('Obs IPF'!B3>0,B3/'Obs IPF'!B3,"") -> -12.731233 | C52: =IF('Obs IPF'!C3>0,C3/'Obs IPF'!C3,"") -> -0.084868805 | D52: =IF('Obs IPF'!D3>0,D3/'Obs IPF'!D3,"") | E52: =IF('Obs IPF'!E3>0,E3/'Obs IPF'!E3,"") | F52: =IF('Obs IPF'!F3>0,F3/'Obs IPF'!F3,"") | G52: =IF('Obs IPF'!G3>0,G3/'Obs IPF'!G3,"") | H52: =IF('Obs IPF'!H3>0,H3/'Obs IPF'!H3,"") | I52: =IF('Obs IPF'!I3>0,I3/'Obs IPF'!I3,"") | ... AT52: =IF('Obs IPF'!AT3>0,AT3/'Obs IPF'!AT3,"") -> 0
A53: Bannock County | B53: =IF('Obs IPF'!B4>0,B4/'Obs IPF'!B4,"") -> 0.6633903 | C53: =IF('Obs IPF'!C4>0,C4/'Obs IPF'!C4,"") | D53: =IF('Obs IPF'!D4>0,D4/'Obs IPF'!D4,"") -> 0.13218497 | E53: =IF('Obs IPF'!E4>0,E4/'Obs IPF'!E4,"") | F53: =IF('Obs IPF'!F4>0,F4/'Obs IPF'!F4,"") | G53: =IF('Obs IPF'!G4>0,G4/'Obs IPF'!G4,"") -> 0.66978696 | H53: =IF('Obs IPF'!H4>0,H4/'Obs IPF'!H4,"") | I53: =IF('Obs IPF'!I4>0,I4/'Obs IPF'!I4,"") | ... AT53: =IF('Obs IPF'!AT4>0,AT4/'Obs IPF'!AT4,"") -> 0
A54: Bear Lake County | B54: =IF('Obs IPF'!B5>0,B5/'Obs IPF'!B5,"") -> 0.97051411 | C54: =IF('Obs IPF'!C5>0,C5/'Obs IPF'!C5,"") | D54: =IF('Obs IPF'!D5>0,D5/'Obs IPF'!D5,"") -> -0.291833 | E54: =IF('Obs IPF'!E5>0,E5/'Obs IPF'!E5,"") -> 0.029862417 | F54: =IF('Obs IPF'!F5>0,F5/'Obs IPF'!F5,"") | G54: =IF('Obs IPF'!G5>0,G5/'Obs IPF'!G5,"") -> -2.1820118 | H54: =IF('Obs IPF'!H5>0,H5/'Obs IPF'!H5,"") | I54: =IF('Obs IPF'!I5>0,I5/'Obs IPF'!I5,"") | ... AT54: =IF('Obs IPF'!AT5>0,AT5/'Obs IPF'!AT5,"") -> 0
A55: Benewah County | B55: =IF('Obs IPF'!B6>0,B6/'Obs IPF'!B6,"") | C55: =IF('Obs IPF'!C6>0,C6/'Obs IPF'!C6,"") | D55: =IF('Obs IPF'!D6>0,D6/'Obs IPF'!D6,"") | E55: =IF('Obs IPF'!E6>0,E6/'Obs IPF'!E6,"") | F55: =IF('Obs IPF'!F6>0,F6/'Obs IPF'!F6,"") -> -0.10157374 | G55: =IF('Obs IPF'!G6>0,G6/'Obs IPF'!G6,"") | H55: =IF('Obs IPF'!H6>0,H6/'Obs IPF'!H6,"") | I55: =IF('Obs IPF'!I6>0,I6/'Obs IPF'!I6,"") | ... AT55: =IF('Obs IPF'!AT6>0,AT6/'Obs IPF'!AT6,"") -> 0
A56: Bingham County | B56: =IF('Obs IPF'!B7>0,B7/'Obs IPF'!B7,"") | C56: =IF('Obs IPF'!C7>0,C7/'Obs IPF'!C7,"") | D56: =IF('Obs IPF'!D7>0,D7/'Obs IPF'!D7,"") -> -2.1119089 | E56: =IF('Obs IPF'!E7>0,E7/'Obs IPF'!E7,"") | F56: =IF('Obs IPF'!F7>0,F7/'Obs IPF'!F7,"") | G56: =IF('Obs IPF'!G7>0,G7/'Obs IPF'!G7,"") -> -0.38341402 | H56: =IF('Obs IPF'!H7>0,H7/'Obs IPF'!H7,"") | I56: =IF('Obs IPF'!I7>0,I7/'Obs IPF'!I7,"") | ... AT56: =IF('Obs IPF'!AT7>0,AT7/'Obs IPF'!AT7,"") -> 0
A57: Blaine County | B57: =IF('Obs IPF'!B8>0,B8/'Obs IPF'!B8,"") | C57: =IF('Obs IPF'!C8>0,C8/'Obs IPF'!C8,"") | D57: =IF('Obs IPF'!D8>0,D8/'Obs IPF'!D8,"") | E57: =IF('Obs IPF'!E8>0,E8/'Obs IPF'!E8,"") | F57: =IF('Obs IPF'!F8>0,F8/'Obs IPF'!F8,"") | G57: =IF('Obs IPF'!G8>0,G8/'Obs IPF'!G8,"") | H57: =IF('Obs IPF'!H8>0,H8/'Obs IPF'!H8,"") -> 0.037762028 | I57: =IF('Obs IPF'!I8>0,I8/'Obs IPF'!I8,"") | ... AT57: =IF('Obs IPF'!AT8>0,AT8/'Obs IPF'!AT8,"") -> 0
A58: Boise County | B58: =IF('Obs IPF'!B9>0,B9/'Obs IPF'!B9,"") -> 0.34961222 | C58: =IF('Obs IPF'!C9>0,C9/'Obs IPF'!C9,"") | D58: =IF('Obs IPF'!D9>0,D9/'Obs IPF'!D9,"") | E58: =IF('Obs IPF'!E9>0,E9/'Obs IPF'!E9,"") | F58: =IF('Obs IPF'!F9>0,F9/'Obs IPF'!F9,"") | G58: =IF('Obs IPF'!G9>0,G9/'Obs IPF'!G9,"") | H58: =IF('Obs IPF'!H9>0,H9/'Obs IPF'!H9,"") | I58: =IF('Obs IPF'!I9>0,I9/'Obs IPF'!I9,"") -> -0.28870051 | ... AT58: =IF('Obs IPF'!AT9>0,AT9/'Obs IPF'!AT9,"") -> 0
A59: Bonner County | B59: =IF('Obs IPF'!B10>0,B10/'Obs IPF'!B10,"") | C59: =IF('Obs IPF'!C10>0,C10/'Obs IPF'!C10,"") | D59: =IF('Obs IPF'!D10>0,D10/'Obs IPF'!D10,"") | E59: =IF('Obs IPF'!E10>0,E10/'Obs IPF'!E10,"") | F59: =IF('Obs IPF'!F10>0,F10/'Obs IPF'!F10,"") | G59: =IF('Obs IPF'!G10>0,G10/'Obs IPF'!G10,"") | H59: =IF('Obs IPF'!H10>0,H10/'Obs IPF'!H10,"") | I59: =IF('Obs IPF'!I10>0,I10/'Obs IPF'!I10,"") | ... AT59: =IF('Obs IPF'!AT10>0,AT10/'Obs IPF'!AT10,"") -> 0
A60: Bonneville County | B60: =IF('Obs IPF'!B11>0,B11/'Obs IPF'!B11,"") -> 0.70565382 | C60: =IF('Obs IPF'!C11>0,C11/'Obs IPF'!C11,"") | D60: =IF('Obs IPF'!D11>0,D11/'Obs IPF'!D11,"") -> -15.725704 | E60: =IF('Obs IPF'!E11>0,E11/'Obs IPF'!E11,"") | F60: =IF('Obs IPF'!F11>0,F11/'Obs IPF'!F11,"") | G60: =IF('Obs IPF'!G11>0,G11/'Obs IPF'!G11,"") -> 0.21917028 | H60: =IF('Obs IPF'!H11>0,H11/'Obs IPF'!H11,"") | I60: =IF('Obs IPF'!I11>0,I11/'Obs IPF'!I11,"") | ... AT60: =IF('Obs IPF'!AT11>0,AT11/'Obs IPF'!AT11,"") -> 0
A61: Boundary County | B61: =IF('Obs IPF'!B12>0,B12/'Obs IPF'!B12,"") | C61: =IF('Obs IPF'!C12>0,C12/'Obs IPF'!C12,"") | D61: =IF('Obs IPF'!D12>0,D12/'Obs IPF'!D12,"") | E61: =IF('Obs IPF'!E12>0,E12/'Obs IPF'!E12,"") | F61: =IF('Obs IPF'!F12>0,F12/'Obs IPF'!F12,"") | G61: =IF('Obs IPF'!G12>0,G12/'Obs IPF'!G12,"") | H61: =IF('Obs IPF'!H12>0,H12/'Obs IPF'!H12,"") | I61: =IF('Obs IPF'!I12>0,I12/'Obs IPF'!I12,"") | ... AT61: =IF('Obs IPF'!AT12>0,AT12/'Obs IPF'!AT12,"") -> 0
A62: Butte County | B62: =IF('Obs IPF'!B13>0,B13/'Obs IPF'!B13,"") | C62: =IF('Obs IPF'!C13>0,C13/'Obs IPF'!C13,"") | D62: =IF('Obs IPF'!D13>0,D13/'Obs IPF'!D13,"") -> -10.196588 | E62: =IF('Obs IPF'!E13>0,E13/'Obs IPF'!E13,"") | F62: =IF('Obs IPF'!F13>0,F13/'Obs IPF'!F13,"") | G62: =IF('Obs IPF'!G13>0,G13/'Obs IPF'!G13,"") -> -2.3293564 | H62: =IF('Obs IPF'!H13>0,H13/'Obs IPF'!H13,"") | I62: =IF('Obs IPF'!I13>0,I13/'Obs IPF'!I13,"") | ... AT62: =IF('Obs IPF'!AT13>0,AT13/'Obs IPF'!AT13,"") -> 0
... A95: Total | B95: =IF('Obs IPF'!B46>0,B46/'Obs IPF'!B46,"") -> 0.001211357 | C95: =IF('Obs IPF'!C46>0,C46/'Obs IPF'!C46,"") -> 0.071764925 | D95: =IF('Obs IPF'!D46>0,D46/'Obs IPF'!D46,"") -> -0.062105829 | E95: =IF('Obs IPF'!E46>0,E46/'Obs IPF'!E46,"") -> 0.080768374 | F95: =IF('Obs IPF'!F46>0,F46/'Obs IPF'!F46,"") -> -0.026118791 | G95: =IF('Obs IPF'!G46>0,G46/'Obs IPF'!G46,"") -> -0.08476443 | H95: =IF('Obs IPF'!H46>0,H46/'Obs IPF'!H46,"") -> 0.11514611 | I95: =IF('Obs IPF'!I46>0,I46/'Obs IPF'!I46,"") -> -0.0011174346 | ... AT95: =IF('Obs IPF'!AT46>0,AT46/'Obs IPF'!AT46,"") -> 0

Sheet Employment
B1: County | C1: old_emp | D1: new_emp | E1: emp_diff | F1: emp_pct_diff | H1: LODES Workers
A2: 0 | B2: Ada | C2: 190769 | D2: 272284 | E2: 81515 | F2: 0.42729689 | H2: 285553
A3: 1 | B3: Adams | C3: 853 | D3: 1150 | E3: 297 | F3: 0.34818288 | H3: 1097
A4: 3 | B4: Bannock | C4: 44347 | D4: 61593 | E4: 17246 | F4: 0.38888764 | H4: 34971
A5: 4 | B5: Bear Lake | C5: 1313 | D5: 1654 | E5: 341 | F5: 0.25971059 | H5: 1552
A6: 5 | B6: Benewah | C6: 3278 | D6: 3358 | E6: 80 | F6: 0.024405125 | H6: 3306
A7: 6 | B7: Bingham | C7: 13871 | D7: 16496 | E7: 2625 | F7: 0.18924375 | H7: 15532
A8: 7 | B8: Blaine | C8: 10917 | D8: 13712 | E8: 2795 | F8: 0.25602272 | H8: 13287
A9: 8 | B9: Boise | C9: 973 | D9: 1488 | E9: 515 | F9: 0.52929085 | H9: 1443
A10: 9 | B10: Bonner | C10: 12868 | D10: 16189 | E10: 3321 | F10: 0.25808206 | H10: 15993
A11: 10 | B11: Bonneville | C11: 61643 | D11: 123574 | E11: 61931 | F11: 1.0046721 | H11: 69191
A12: 11 | B12: Boundary | C12: 3072 | D12: 3878 | E12: 806 | F12: 0.26236979 | H12: 3771
A13: 12 | B13: Butte | C13: 2121 | D13: 696 | E13: -1425 | F13: -0.6718529 | H13: 644
... A45: 46 | B45: Washington | C45: 23197 | D45: 31987 | E45: 8790 | F45: 0.37892831 | H45: 3018
A46: 47

Sheet LODES
